Workbook

Sheet PSAT
A1: Posto | B1: Lat | C1: Lon | D1: Subbacia Associada | E1: Coluna1 | F1: Coluna2 | G1: Coluna3
A2: PSATAGV | B2: -19.89 | C2: -50.35 | D2: Água Vermelha
A3: PSATCMG | B3: -21.28 | C3: -44.63 | D3: Camargos
A4: PSATCES | B4: -20.25 | C4: -48.16 | D4: Capão Escuro
A5: PSATELC | B5: -21.6 | C5: -46.95 | D5: Euclides da Cunha
A6: PSATFUN | B6: -21.14 | C6: -45.04 | D6: Funil
A7: PSATFUR | B7: -20.67 | C7: -46.32 | D7: Furnas
A8: PSATMRB | B8: -20.3 | C8: -49.18 | D8: Marimbondo
A9: PSATPRG | B9: -21.59 | C9: -45.67 | D9: Paraguaçu
A10: PSATPAS | B10: -21.02 | C10: -48.18 | D10: Passagem
A11: PSATPTB | B11: -21.61 | C11: -45.49 | D11: Porto dos Buenos
A12: PSATPTC | B12: -20 | C12: -48.55 | D12: Porto Colombia
A13: PSATFZA | B13: -26 | C13: -51.65 | D13: Foz do Areia
... A129: PSATSALT | B129: -50.679 | C129: -29.315 | D129: Salto RS

Sheet RESUMO
B1: MODELO | C1: SIGLA | D1: BACIA | E1: SUBBACIA | F1: SUBBACIA MODELADA | G1: TIPO | H1: AUX | I1: Código 1 | J1: Código 2 | K1: n bacias | L1: i_bacia | M1: CÓDIGO BDT | N1: CÓDIGO FLU ANA | O1: PSAT
A2: 1 | B2: SMAP GRANDE E PARANAIBA | C2: SMP_GRPRNB | D2: Grande | E2: {=IF(K2=0,F2,TRIM(OFFSET(INDIRECT("'"&B2&"'!A1"),I2+L2,1)))} -> Camargos | F2: {=TRIM(SUBSTITUTE(INDEX(INDIRECT("'"&B2&"'!A1:A1000"),H2),"Sub-bacia modelada:",""))} -> Camargos | G2: =IF(K2=0,"BASE - POSTO FLU",IF(OR(E2=F2,K2=1),"BASE - RESERVATÓRIO","NÃO BASE")) -> BASE - RESERVATÓRIO | H2: {=SMALL(ROW(INDIRECT("'"&B2&"'!A1:A1000"))*IF(ISNUMBER(FIND("Sub-bacia modelada:",INDIRECT("'"&B2&"'!A1:A1000"))),1,9999),RESUMO!A2)} -> 1 | I2: =MATCH("Código",INDIRECT("'"&B2&"'!A"&H2&":A"&H2+20),0)+H2-1 -> 4 | J2: =MATCH("Código",INDIRECT("'"&B2&"'!A"&I2+1&":A"&H2+20),0)+I2 -> 9 | K2: =COUNT(INDIRECT("'"&B2&"'!A"&I2&":A"&J2)) -> 2 | L2: =COUNTIF($F$1:F2,F2) -> 1 | M2: {=IF(Tabela2[[#This Row],[TIPO]]<>"BASE - POSTO FLU",_xlfn.XLOOKUP(Tabela2[[#This Row],[SUBBACIA]],INDIRECT("'"&Tabela2[[#This Row],[MODELO]]&"'!B1:B5000"),INDIRECT("'"&Tabela2[[#This Row],[MODELO]]&"'!A1:A5000")),"")} -> 1 | N2: {=IF(Tabela2[[#This Row],[TIPO]]="BASE - POSTO FLU",OFFSET(INDIRECT("'"&Tabela2[[#This Row],[MODELO]]&"'!A1"),MATCH("Sub-bacia modelada: "&Tabela2[[#This Row],[SUBBACIA]],INDIRECT("'"&Tabela2[[#This Row],[MODELO]]&"'!A1:A5000"),0)+8,0),"")} | O2: {=IF(Tabela2[[#This Row],[TIPO]]="NÃO BASE","",INDEX(INDIRECT("'"&Tabela2[[#This Row],[MODELO]]&"'!$A$1:$A$5000"),MATCH("Precipitação verificada:",OFFSET(INDIRECT("'"&Tabela2[[#This Row],[MODELO]]&"'!$A$1"),MATCH("Sub-bacia modelada: "&Tabela2[[#This Row],[SUBBACIA MODELADA]],INDIRECT("'"&Tabela2[[#This Row],[MODELO]]&"'!$A$1:$A$5000"),0),0,25,1),0)+MATCH("Sub-bacia modelada: "&Tabela2[[#This Row],[SUBBACIA MODELADA]],INDIRECT("'"&Tabela2[[#This Row],[MODELO]]&"'!$A$1:$A$5000"),0)+3))} -> PSATCMG
A3: =IF(AND(K2>1,L2<>K2),A2,A2+1) -> 1 | B3: SMAP GRANDE E PARANAIBA | C3: SMP_GRPRNB | D3: Grande | E3: {=IF(K3=0,F3,TRIM(OFFSET(INDIRECT("'"&B3&"'!A1"),I3+L3,1)))} -> Itutinga | F3: {=TRIM(SUBSTITUTE(INDEX(INDIRECT("'"&B3&"'!A1:A1000"),H3),"Sub-bacia modelada:",""))} -> Camargos | G3: =IF(K3=0,"BASE - POSTO FLU",IF(OR(E3=F3,K3=1),"BASE - RESERVATÓRIO","NÃO BASE")) -> NÃO BASE | H3: {=SMALL(ROW(INDIRECT("'"&B3&"'!A1:A1000"))*IF(ISNUMBER(FIND("Sub-bacia modelada:",INDIRECT("'"&B3&"'!A1:A1000"))),1,9999),RESUMO!A3)} -> 1 | I3: =MATCH("Código",INDIRECT("'"&B3&"'!A"&H3&":A"&H3+20),0)+H3-1 -> 4 | J3: =MATCH("Código",INDIRECT("'"&B3&"'!A"&I3+1&":A"&H3+20),0)+I3 -> 9 | K3: =COUNT(INDIRECT("'"&B3&"'!A"&I3&":A"&J3)) -> 2 | L3: =COUNTIF($F$1:F3,F3) -> 2 | M3: {=IF(Tabela2[[#This Row],[TIPO]]<>"BASE - POSTO FLU",_xlfn.XLOOKUP(Tabela2[[#This Row],[SUBBACIA]],INDIRECT("'"&Tabela2[[#This Row],[MODELO]]&"'!B1:B5000"),INDIRECT("'"&Tabela2[[#This Row],[MODELO]]&"'!A1:A5000")),"")} -> 2 | N3: {=IF(Tabela2[[#This Row],[TIPO]]="BASE - POSTO FLU",OFFSET(INDIRECT("'"&Tabela2[[#This Row],[MODELO]]&"'!A1"),MATCH("Sub-bacia modelada: "&Tabela2[[#This Row],[SUBBACIA]],INDIRECT("'"&Tabela2[[#This Row],[MODELO]]&"'!A1:A5000"),0)+8,0),"")} | O3: {=IF(Tabela2[[#This Row],[TIPO]]="NÃO BASE","",INDEX(INDIRECT("'"&Tabela2[[#This Row],[MODELO]]&"'!$A$1:$A$5000"),MATCH("Precipitação verificada:",OFFSET(INDIRECT("'"&Tabela2[[#This Row],[MODELO]]&"'!$A$1"),MATCH("Sub-bacia modelada: "&Tabela2[[#This Row],[SUBBACIA MODELADA]],INDIRECT("'"&Tabela2[[#This Row],[MODELO]]&"'!$A$1:$A$5000"),0),0,25,1),0)+MATCH("Sub-bacia modelada: "&Tabela2[[#This Row],[SUBBACIA MODELADA]],INDIRECT("'"&Tabela2[[#This Row],[MODELO]]&"'!$A$1:$A$5000"),0)+3))}
A4: =IF(AND(K3>1,L3<>K3),A3,A3+1) -> 2 | B4: SMAP GRANDE E PARANAIBA | C4: SMP_GRPRNB | D4: Grande | E4: {=IF(K4=0,F4,TRIM(OFFSET(INDIRECT("'"&B4&"'!A1"),I4+L4,1)))} -> Funil-MG | F4: {=TRIM(SUBSTITUTE(INDEX(INDIRECT("'"&B4&"'!A1:A1000"),H4),"Sub-bacia modelada:",""))} -> Funil-MG | G4: =IF(K4=0,"BASE - POSTO FLU",IF(OR(E4=F4,K4=1),"BASE - RESERVATÓRIO","NÃO BASE")) -> BASE - RESERVATÓRIO | H4: {=SMALL(ROW(INDIRECT("'"&B4&"'!A1:A1000"))*IF(ISNUMBER(FIND("Sub-bacia modelada:",INDIRECT("'"&B4&"'!A1:A1000"))),1,9999),RESUMO!A4)} -> 23 | I4: =MATCH("Código",INDIRECT("'"&B4&"'!A"&H4&":A"&H4+20),0)+H4-1 -> 26 | J4: =MATCH("Código",INDIRECT("'"&B4&"'!A"&I4+1&":A"&H4+20),0)+I4 -> 30 | K4: =COUNT(INDIRECT("'"&B4&"'!A"&I4&":A"&J4)) -> 1 | L4: =COUNTIF($F$1:F4,F4) -> 1 | M4: {=IF(Tabela2[[#This Row],[TIPO]]<>"BASE - POSTO FLU",_xlfn.XLOOKUP(Tabela2[[#This Row],[SUBBACIA]],INDIRECT("'"&Tabela2[[#This Row],[MODELO]]&"'!B1:B5000"),INDIRECT("'"&Tabela2[[#This Row],[MODELO]]&"'!A1:A5000")),"")} -> 211 | N4: {=IF(Tabela2[[#This Row],[TIPO]]="BASE - POSTO FLU",OFFSET(INDIRECT("'"&Tabela2[[#This Row],[MODELO]]&"'!A1"),MATCH("Sub-bacia modelada: "&Tabela2[[#This Row],[SUBBACIA]],INDIRECT("'"&Tabela2[[#This Row],[MODELO]]&"'!A1:A5000"),0)+8,0),"")} | O4: {=IF(Tabela2[[#This Row],[TIPO]]="NÃO BASE","",INDEX(INDIRECT("'"&Tabela2[[#This Row],[MODELO]]&"'!$A$1:$A$5000"),MATCH("Precipitação verificada:",OFFSET(INDIRECT("'"&Tabela2[[#This Row],[MODELO]]&"'!$A$1"),MATCH("Sub-bacia modelada: "&Tabela2[[#This Row],[SUBBACIA MODELADA]],INDIRECT("'"&Tabela2[[#This Row],[MODELO]]&"'!$A$1:$A$5000"),0),0,25,1),0)+MATCH("Sub-bacia modelada: "&Tabela2[[#This Row],[SUBBACIA MODELADA]],INDIRECT("'"&Tabela2[[#This Row],[MODELO]]&"'!$A$1:$A$5000"),0)+3))} -> PSATFUN
A5: =IF(AND(K4>1,L4<>K4),A4,A4+1) -> 3 | B5: SMAP GRANDE E PARANAIBA | C5: SMP_GRPRNB | D5: Grande | E5: {=IF(K5=0,F5,TRIM(OFFSET(INDIRECT("'"&B5&"'!A1"),I5+L5,1)))} -> Furnas | F5: {=TRIM(SUBSTITUTE(INDEX(INDIRECT("'"&B5&"'!A1:A1000"),H5),"Sub-bacia modelada:",""))} -> Furnas | G5: =IF(K5=0,"BASE - POSTO FLU",IF(OR(E5=F5,K5=1),"BASE - RESERVATÓRIO","NÃO BASE")) -> BASE - RESERVATÓRIO | H5: {=SMALL(ROW(INDIRECT("'"&B5&"'!A1:A1000"))*IF(ISNUMBER(FIND("Sub-bacia modelada:",INDIRECT("'"&B5&"'!A1:A1000"))),1,9999),RESUMO!A5)} -> 44 | I5: =MATCH("Código",INDIRECT("'"&B5&"'!A"&H5&":A"&H5+20),0)+H5-1 -> 47 | J5: =MATCH("Código",INDIRECT("'"&B5&"'!A"&I5+1&":A"&H5+20),0)+I5 -> 51 | K5: =COUNT(INDIRECT("'"&B5&"'!A"&I5&":A"&J5)) -> 1 | L5: =COUNTIF($F$1:F5,F5) -> 1 | M5: {=IF(Tabela2[[#This Row],[TIPO]]<>"BASE - POSTO FLU",_xlfn.XLOOKUP(Tabela2[[#This Row],[SUBBACIA]],INDIRECT("'"&Tabela2[[#This Row],[MODELO]]&"'!B1:B5000"),INDIRECT("'"&Tabela2[[#This Row],[MODELO]]&"'!A1:A5000")),"")} -> 6 | N5: {=IF(Tabela2[[#This Row],[TIPO]]="BASE - POSTO FLU",OFFSET(INDIRECT("'"&Tabela2[[#This Row],[MODELO]]&"'!A1"),MATCH("Sub-bacia modelada: "&Tabela2[[#This Row],[SUBBACIA]],INDIRECT("'"&Tabela2[[#This Row],[MODELO]]&"'!A1:A5000"),0)+8,0),"")} | O5: {=IF(Tabela2[[#This Row],[TIPO]]="NÃO BASE","",INDEX(INDIRECT("'"&Tabela2[[#This Row],[MODELO]]&"'!$A$1:$A$5000"),MATCH("Precipitação verificada:",OFFSET(INDIRECT("'"&Tabela2[[#This Row],[MODELO]]&"'!$A$1"),MATCH("Sub-bacia modelada: "&Tabela2[[#This Row],[SUBBACIA MODELADA]],INDIRECT("'"&Tabela2[[#This Row],[MODELO]]&"'!$A$1:$A$5000"),0),0,25,1),0)+MATCH("Sub-bacia modelada: "&Tabela2[[#This Row],[SUBBACIA MODELADA]],INDIRECT("'"&Tabela2[[#This Row],[MODELO]]&"'!$A$1:$A$5000"),0)+3))} -> PSATFUR
A6: =IF(AND(K5>1,L5<>K5),A5,A5+1) -> 4 | B6: SMAP GRANDE E PARANAIBA | C6: SMP_GRPRNB | D6: Grande | E6: {=IF(K6=0,F6,TRIM(OFFSET(INDIRECT("'"&B6&"'!A1"),I6+L6,1)))} -> Paraguaçu | F6: {=TRIM(SUBSTITUTE(INDEX(INDIRECT("'"&B6&"'!A1:A1000"),H6),"Sub-bacia modelada:",""))} -> Paraguaçu | G6: =IF(K6=0,"BASE - POSTO FLU",IF(OR(E6=F6,K6=1),"BASE - RESERVATÓRIO","NÃO BASE")) -> BASE - POSTO FLU | H6: {=SMALL(ROW(INDIRECT("'"&B6&"'!A1:A1000"))*IF(ISNUMBER(FIND("Sub-bacia modelada:",INDIRECT("'"&B6&"'!A1:A1000"))),1,9999),RESUMO!A6)} -> 66 | I6: =MATCH("Código",INDIRECT("'"&B6&"'!A"&H6&":A"&H6+20),0)+H6-1 -> 69 | J6: =MATCH("Código",INDIRECT("'"&B6&"'!A"&I6+1&":A"&H6+20),0)+I6 -> 73 | K6: =COUNT(INDIRECT("'"&B6&"'!A"&I6&":A"&J6)) -> 0 | L6: =COUNTIF($F$1:F6,F6) -> 1 | M6: {=IF(Tabela2[[#This Row],[TIPO]]<>"BASE - POSTO FLU",_xlfn.XLOOKUP(Tabela2[[#This Row],[SUBBACIA]],INDIRECT("'"&Tabela2[[#This Row],[MODELO]]&"'!B1:B5000"),INDIRECT("'"&Tabela2[[#This Row],[MODELO]]&"'!A1:A5000")),"")} | N6: {=IF(Tabela2[[#This Row],[TIPO]]="BASE - POSTO FLU",OFFSET(INDIRECT("'"&Tabela2[[#This Row],[MODELO]]&"'!A1"),MATCH("Sub-bacia modelada: "&Tabela2[[#This Row],[SUBBACIA]],INDIRECT("'"&Tabela2[[#This Row],[MODELO]]&"'!A1:A5000"),0)+8,0),"")} -> 61425000 | O6: {=IF(Tabela2[[#This Row],[TIPO]]="NÃO BASE","",INDEX(INDIRECT("'"&Tabela2[[#This Row],[MODELO]]&"'!$A$1:$A$5000"),MATCH("Precipitação verificada:",OFFSET(INDIRECT("'"&Tabela2[[#This Row],[MODELO]]&"'!$A$1"),MATCH("Sub-bacia modelada: "&Tabela2[[#This Row],[SUBBACIA MODELADA]],INDIRECT("'"&Tabela2[[#This Row],[MODELO]]&"'!$A$1:$A$5000"),0),0,25,1),0)+MATCH("Sub-bacia modelada: "&Tabela2[[#This Row],[SUBBACIA MODELADA]],INDIRECT("'"&Tabela2[[#This Row],[MODELO]]&"'!$A$1:$A$5000"),0)+3))} -> PSATPRG
A7: =IF(AND(K6>1,L6<>K6),A6,A6+1) -> 5 | B7: SMAP GRANDE E PARANAIBA | C7: SMP_GRPRNB | D7: Grande | E7: {=IF(K7=0,F7,TRIM(OFFSET(INDIRECT("'"&B7&"'!A1"),I7+L7,1)))} -> Porto dos Buenos | F7: {=TRIM(SUBSTITUTE(INDEX(INDIRECT("'"&B7&"'!A1:A1000"),H7),"Sub-bacia modelada:",""))} -> Porto dos Buenos | G7: =IF(K7=0,"BASE - POSTO FLU",IF(OR(E7=F7,K7=1),"BASE - RESERVATÓRIO","NÃO BASE")) -> BASE - POSTO FLU | H7: {=SMALL(ROW(INDIRECT("'"&B7&"'!A1:A1000"))*IF(ISNUMBER(FIND("Sub-bacia modelada:",INDIRECT("'"&B7&"'!A1:A1000"))),1,9999),RESUMO!A7)} -> 87 | I7: =MATCH("Código",INDIRECT("'"&B7&"'!A"&H7&":A"&H7+20),0)+H7-1 -> 90 | J7: =MATCH("Código",INDIRECT("'"&B7&"'!A"&I7+1&":A"&H7+20),0)+I7 -> 94 | K7: =COUNT(INDIRECT("'"&B7&"'!A"&I7&":A"&J7)) -> 0 | L7: =COUNTIF($F$1:F7,F7) -> 1 | M7: {=IF(Tabela2[[#This Row],[TIPO]]<>"BASE - POSTO FLU",_xlfn.XLOOKUP(Tabela2[[#This Row],[SUBBACIA]],INDIRECT("'"&Tabela2[[#This Row],[MODELO]]&"'!B1:B5000"),INDIRECT("'"&Tabela2[[#This Row],[MODELO]]&"'!A1:A5000")),"")} | N7: {=IF(Tabela2[[#This Row],[TIPO]]="BASE - POSTO FLU",OFFSET(INDIRECT("'"&Tabela2[[#This Row],[MODELO]]&"'!A1"),MATCH("Sub-bacia modelada: "&Tabela2[[#This Row],[SUBBACIA]],INDIRECT("'"&Tabela2[[#This Row],[MODELO]]&"'!A1:A5000"),0)+8,0),"")} -> 61537000 | O7: {=IF(Tabela2[[#This Row],[TIPO]]="NÃO BASE","",INDEX(INDIRECT("'"&Tabela2[[#This Row],[MODELO]]&"'!$A$1:$A$5000"),MATCH("Precipitação verificada:",OFFSET(INDIRECT("'"&Tabela2[[#This Row],[MODELO]]&"'!$A$1"),MATCH("Sub-bacia modelada: "&Tabela2[[#This Row],[SUBBACIA MODELADA]],INDIRECT("'"&Tabela2[[#This Row],[MODELO]]&"'!$A$1:$A$5000"),0),0,25,1),0)+MATCH("Sub-bacia modelada: "&Tabela2[[#This Row],[SUBBACIA MODELADA]],INDIRECT("'"&Tabela2[[#This Row],[MODELO]]&"'!$A$1:$A$5000"),0)+3))} -> PSATPTB
A8: =IF(AND(K7>1,L7<>K7),A7,A7+1) -> 6 | B8: SMAP GRANDE E PARANAIBA | C8: SMP_GRPRNB | D8: Grande | E8: {=IF(K8=0,F8,TRIM(OFFSET(INDIRECT("'"&B8&"'!A1"),I8+L8,1)))} -> Capão Escuro | F8: {=TRIM(SUBSTITUTE(INDEX(INDIRECT("'"&B8&"'!A1:A1000"),H8),"Sub-bacia modelada:",""))} -> Capão Escuro | G8: =IF(K8=0,"BASE - POSTO FLU",IF(OR(E8=F8,K8=1),"BASE - RESERVATÓRIO","NÃO BASE")) -> BASE - POSTO FLU | H8: {=SMALL(ROW(INDIRECT("'"&B8&"'!A1:A1000"))*IF(ISNUMBER(FIND("Sub-bacia modelada:",INDIRECT("'"&B8&"'!A1:A1000"))),1,9999),RESUMO!A8)} -> 108 | I8: =MATCH("Código",INDIRECT("'"&B8&"'!A"&H8&":A"&H8+20),0)+H8-1 -> 111 | J8: =MATCH("Código",INDIRECT("'"&B8&"'!A"&I8+1&":A"&H8+20),0)+I8 -> 115 | K8: =COUNT(INDIRECT("'"&B8&"'!A"&I8&":A"&J8)) -> 0 | L8: =COUNTIF($F$1:F8,F8) -> 1 | M8: {=IF(Tabela2[[#This Row],[TIPO]]<>"BASE - POSTO FLU",_xlfn.XLOOKUP(Tabela2[[#This Row],[SUBBACIA]],INDIRECT("'"&Tabela2[[#This Row],[MODELO]]&"'!B1:B5000"),INDIRECT("'"&Tabela2[[#This Row],[MODELO]]&"'!A1:A5000")),"")} | N8: {=IF(Tabela2[[#This Row],[TIPO]]="BASE - POSTO FLU",OFFSET(INDIRECT("'"&Tabela2[[#This Row],[MODELO]]&"'!A1"),MATCH("Sub-bacia modelada: "&Tabela2[[#This Row],[SUBBACIA]],INDIRECT("'"&Tabela2[[#This Row],[MODELO]]&"'!A1:A5000"),0)+8,0),"")} -> 61787000 | O8: {=IF(Tabela2[[#This Row],[TIPO]]="NÃO BASE","",INDEX(INDIRECT("'"&Tabela2[[#This Row],[MODELO]]&"'!$A$1:$A$5000"),MATCH("Precipitação verificada:",OFFSET(INDIRECT("'"&Tabela2[[#This Row],[MODELO]]&"'!$A$1"),MATCH("Sub-bacia modelada: "&Tabela2[[#This Row],[SUBBACIA MODELADA]],INDIRECT("'"&Tabela2[[#This Row],[MODELO]]&"'!$A$1:$A$5000"),0),0,25,1),0)+MATCH("Sub-bacia modelada: "&Tabela2[[#This Row],[SUBBACIA MODELADA]],INDIRECT("'"&Tabela2[[#This Row],[MODELO]]&"'!$A$1:$A$5000"),0)+3))} -> PSATCES
A9: =IF(AND(K8>1,L8<>K8),A8,A8+1) -> 7 | B9: SMAP GRANDE E PARANAIBA | C9: SMP_GRPRNB | D9: Grande | E9: {=IF(K9=0,F9,TRIM(OFFSET(INDIRECT("'"&B9&"'!A1"),I9+L9,1)))} -> Mascarenhas de Moraes | F9: {=TRIM(SUBSTITUTE(INDEX(INDIRECT("'"&B9&"'!A1:A1000"),H9),"Sub-bacia modelada:",""))} -> Porto Colômbia | G9: =IF(K9=0,"BASE - POSTO FLU",IF(OR(E9=F9,K9=1),"BASE - RESERVATÓRIO","NÃO BASE")) -> NÃO BASE | H9: {=SMALL(ROW(INDIRECT("'"&B9&"'!A1:A1000"))*IF(ISNUMBER(FIND("Sub-bacia modelada:",INDIRECT("'"&B9&"'!A1:A1000"))),1,9999),RESUMO!A9)} -> 129 | I9: =MATCH("Código",INDIRECT("'"&B9&"'!A"&H9&":A"&H9+20),0)+H9-1 -> 132 | J9: =MATCH("Código",INDIRECT("'"&B9&"'!A"&I9+1&":A"&H9+20),0)+I9 -> 141 | K9: =COUNT(INDIRECT("'"&B9&"'!A"&I9&":A"&J9)) -> 6 | L9: =COUNTIF($F$1:F9,F9) -> 1 | M9: {=IF(Tabela2[[#This Row],[TIPO]]<>"BASE - POSTO FLU",_xlfn.XLOOKUP(Tabela2[[#This Row],[SUBBACIA]],INDIRECT("'"&Tabela2[[#This Row],[MODELO]]&"'!B1:B5000"),INDIRECT("'"&Tabela2[[#This Row],[MODELO]]&"'!A1:A5000")),"")} -> 7 | N9: {=IF(Tabela2[[#This Row],[TIPO]]="BASE - POSTO FLU",OFFSET(INDIRECT("'"&Tabela2[[#This Row],[MODELO]]&"'!A1"),MATCH("Sub-bacia modelada: "&Tabela2[[#This Row],[SUBBACIA]],INDIRECT("'"&Tabela2[[#This Row],[MODELO]]&"'!A1:A5000"),0)+8,0),"")} | O9: {=IF(Tabela2[[#This Row],[TIPO]]="NÃO BASE","",INDEX(INDIRECT("'"&Tabela2[[#This Row],[MODELO]]&"'!$A$1:$A$5000"),MATCH("Precipitação verificada:",OFFSET(INDIRECT("'"&Tabela2[[#This Row],[MODELO]]&"'!$A$1"),MATCH("Sub-bacia modelada: "&Tabela2[[#This Row],[SUBBACIA MODELADA]],INDIRECT("'"&Tabela2[[#This Row],[MODELO]]&"'!$A$1:$A$5000"),0),0,25,1),0)+MATCH("Sub-bacia modelada: "&Tabela2[[#This Row],[SUBBACIA MODELADA]],INDIRECT("'"&Tabela2[[#This Row],[MODELO]]&"'!$A$1:$A$5000"),0)+3))}
A10: =IF(AND(K9>1,L9<>K9),A9,A9+1) -> 7 | B10: SMAP GRANDE E PARANAIBA | C10: SMP_GRPRNB | D10: Grande | E10: {=IF(K10=0,F10,TRIM(OFFSET(INDIRECT("'"&B10&"'!A1"),I10+L10,1)))} -> L.C. Barreto | F10: {=TRIM(SUBSTITUTE(INDEX(INDIRECT("'"&B10&"'!A1:A1000"),H10),"Sub-bacia modelada:",""))} -> Porto Colômbia | G10: =IF(K10=0,"BASE - POSTO FLU",IF(OR(E10=F10,K10=1),"BASE - RESERVATÓRIO","NÃO BASE")) -> NÃO BASE | H10: {=SMALL(ROW(INDIRECT("'"&B10&"'!A1:A1000"))*IF(ISNUMBER(FIND("Sub-bacia modelada:",INDIRECT("'"&B10&"'!A1:A1000"))),1,9999),RESUMO!A10)} -> 129 | I10: =MATCH("Código",INDIRECT("'"&B10&"'!A"&H10&":A"&H10+20),0)+H10-1 -> 132 | J10: =MATCH("Código",INDIRECT("'"&B10&"'!A"&I10+1&":A"&H10+20),0)+I10 -> 141 | K10: =COUNT(INDIRECT("'"&B10&"'!A"&I10&":A"&J10)) -> 6 | L10: =COUNTIF($F$1:F10,F10) -> 2 | M10: {=IF(Tabela2[[#This Row],[TIPO]]<>"BASE - POSTO FLU",_xlfn.XLOOKUP(Tabela2[[#This Row],[SUBBACIA]],INDIRECT("'"&Tabela2[[#This Row],[MODELO]]&"'!B1:B5000"),INDIRECT("'"&Tabela2[[#This Row],[MODELO]]&"'!A1:A5000")),"")} -> 8 | N10: {=IF(Tabela2[[#This Row],[TIPO]]="BASE - POSTO FLU",OFFSET(INDIRECT("'"&Tabela2[[#This Row],[MODELO]]&"'!A1"),MATCH("Sub-bacia modelada: "&Tabela2[[#This Row],[SUBBACIA]],INDIRECT("'"&Tabela2[[#This Row],[MODELO]]&"'!A1:A5000"),0)+8,0),"")} | O10: {=IF(Tabela2[[#This Row],[TIPO]]="NÃO BASE","",INDEX(INDIRECT("'"&Tabela2[[#This Row],[MODELO]]&"'!$A$1:$A$5000"),MATCH("Precipitação verificada:",OFFSET(INDIRECT("'"&Tabela2[[#This Row],[MODELO]]&"'!$A$1"),MATCH("Sub-bacia modelada: "&Tabela2[[#This Row],[SUBBACIA MODELADA]],INDIRECT("'"&Tabela2[[#This Row],[MODELO]]&"'!$A$1:$A$5000"),0),0,25,1),0)+MATCH("Sub-bacia modelada: "&Tabela2[[#This Row],[SUBBACIA MODELADA]],INDIRECT("'"&Tabela2[[#This Row],[MODELO]]&"'!$A$1:$A$5000"),0)+3))}
A11: =IF(AND(K10>1,L10<>K10),A10,A10+1) -> 7 | B11: SMAP GRANDE E PARANAIBA | C11: SMP_GRPRNB | D11: Grande | E11: {=IF(K11=0,F11,TRIM(OFFSET(INDIRECT("'"&B11&"'!A1"),I11+L11,1)))} -> Jaguara | F11: {=TRIM(SUBSTITUTE(INDEX(INDIRECT("'"&B11&"'!A1:A1000"),H11),"Sub-bacia modelada:",""))} -> Porto Colômbia | G11: =IF(K11=0,"BASE - POSTO FLU",IF(OR(E11=F11,K11=1),"BASE - RESERVATÓRIO","NÃO BASE")) -> NÃO BASE | H11: {=SMALL(ROW(INDIRECT("'"&B11&"'!A1:A1000"))*IF(ISNUMBER(FIND("Sub-bacia modelada:",INDIRECT("'"&B11&"'!A1:A1000"))),1,9999),RESUMO!A11)} -> 129 | I11: =MATCH("Código",INDIRECT("'"&B11&"'!A"&H11&":A"&H11+20),0)+H11-1 -> 132 | J11: =MATCH("Código",INDIRECT("'"&B11&"'!A"&I11+1&":A"&H11+20),0)+I11 -> 141 | K11: =COUNT(INDIRECT("'"&B11&"'!A"&I11&":A"&J11)) -> 6 | L11: =COUNTIF($F$1:F11,F11) -> 3 | M11: {=IF(Tabela2[[#This Row],[TIPO]]<>"BASE - POSTO FLU",_xlfn.XLOOKUP(Tabela2[[#This Row],[SUBBACIA]],INDIRECT("'"&Tabela2[[#This Row],[MODELO]]&"'!B1:B5000"),INDIRECT("'"&Tabela2[[#This Row],[MODELO]]&"'!A1:A5000")),"")} -> 9 | N11: {=IF(Tabela2[[#This Row],[TIPO]]="BASE - POSTO FLU",OFFSET(INDIRECT("'"&Tabela2[[#This Row],[MODELO]]&"'!A1"),MATCH("Sub-bacia modelada: "&Tabela2[[#This Row],[SUBBACIA]],INDIRECT("'"&Tabela2[[#This Row],[MODELO]]&"'!A1:A5000"),0)+8,0),"")} | O11: {=IF(Tabela2[[#This Row],[TIPO]]="NÃO BASE","",INDEX(INDIRECT("'"&Tabela2[[#This Row],[MODELO]]&"'!$A$1:$A$5000"),MATCH("Precipitação verificada:",OFFSET(INDIRECT("'"&Tabela2[[#This Row],[MODELO]]&"'!$A$1"),MATCH("Sub-bacia modelada: "&Tabela2[[#This Row],[SUBBACIA MODELADA]],INDIRECT("'"&Tabela2[[#This Row],[MODELO]]&"'!$A$1:$A$5000"),0),0,25,1),0)+MATCH("Sub-bacia modelada: "&Tabela2[[#This Row],[SUBBACIA MODELADA]],INDIRECT("'"&Tabela2[[#This Row],[MODELO]]&"'!$A$1:$A$5000"),0)+3))}
A12: =IF(AND(K11>1,L11<>K11),A11,A11+1) -> 7 | B12: SMAP GRANDE E PARANAIBA | C12: SMP_GRPRNB | D12: Grande | E12: {=IF(K12=0,F12,TRIM(OFFSET(INDIRECT("'"&B12&"'!A1"),I12+L12,1)))} -> Igarapava | F12: {=TRIM(SUBSTITUTE(INDEX(INDIRECT("'"&B12&"'!A1:A1000"),H12),"Sub-bacia modelada:",""))} -> Porto Colômbia | G12: =IF(K12=0,"BASE - POSTO FLU",IF(OR(E12=F12,K12=1),"BASE - RESERVATÓRIO","NÃO BASE")) -> NÃO BASE | H12: {=SMALL(ROW(INDIRECT("'"&B12&"'!A1:A1000"))*IF(ISNUMBER(FIND("Sub-bacia modelada:",INDIRECT("'"&B12&"'!A1:A1000"))),1,9999),RESUMO!A12)} -> 129 | I12: =MATCH("Código",INDIRECT("'"&B12&"'!A"&H12&":A"&H12+20),0)+H12-1 -> 132 | J12: =MATCH("Código",INDIRECT("'"&B12&"'!A"&I12+1&":A"&H12+20),0)+I12 -> 141 | K12: =COUNT(INDIRECT("'"&B12&"'!A"&I12&":A"&J12)) -> 6 | L12: =COUNTIF($F$1:F12,F12) -> 4 | M12: {=IF(Tabela2[[#This Row],[TIPO]]<>"BASE - POSTO FLU",_xlfn.XLOOKUP(Tabela2[[#This Row],[SUBBACIA]],INDIRECT("'"&Tabela2[[#This Row],[MODELO]]&"'!B1:B5000"),INDIRECT("'"&Tabela2[[#This Row],[MODELO]]&"'!A1:A5000")),"")} -> 10 | N12: {=IF(Tabela2[[#This Row],[TIPO]]="BASE - POSTO FLU",OFFSET(INDIRECT("'"&Tabela2[[#This Row],[MODELO]]&"'!A1"),MATCH("Sub-bacia modelada: "&Tabela2[[#This Row],[SUBBACIA]],INDIRECT("'"&Tabela2[[#This Row],[MODELO]]&"'!A1:A5000"),0)+8,0),"")} | O12: {=IF(Tabela2[[#This Row],[TIPO]]="NÃO BASE","",INDEX(INDIRECT("'"&Tabela2[[#This Row],[MODELO]]&"'!$A$1:$A$5000"),MATCH("Precipitação verificada:",OFFSET(INDIRECT("'"&Tabela2[[#This Row],[MODELO]]&"'!$A$1"),MATCH("Sub-bacia modelada: "&Tabela2[[#This Row],[SUBBACIA MODELADA]],INDIRECT("'"&Tabela2[[#This Row],[MODELO]]&"'!$A$1:$A$5000"),0),0,25,1),0)+MATCH("Sub-bacia modelada: "&Tabela2[[#This Row],[SUBBACIA MODELADA]],INDIRECT("'"&Tabela2[[#This Row],[MODELO]]&"'!$A$1:$A$5000"),0)+3))}
A13: =IF(AND(K12>1,L12<>K12),A12,A12+1) -> 7 | B13: SMAP GRANDE E PARANAIBA | C13: SMP_GRPRNB | D13: Grande | E13: {=IF(K13=0,F13,TRIM(OFFSET(INDIRECT("'"&B13&"'!A1"),I13+L13,1)))} -> Volta Grande | F13: {=TRIM(SUBSTITUTE(INDEX(INDIRECT("'"&B13&"'!A1:A1000"),H13),"Sub-bacia modelada:",""))} -> Porto Colômbia | G13: =IF(K13=0,"BASE - POSTO FLU",IF(OR(E13=F13,K13=1),"BASE - RESERVATÓRIO","NÃO BASE")) -> NÃO BASE | H13: {=SMALL(ROW(INDIRECT("'"&B13&"'!A1:A1000"))*IF(ISNUMBER(FIND("Sub-bacia modelada:",INDIRECT("'"&B13&"'!A1:A1000"))),1,9999),RESUMO!A13)} -> 129 | I13: =MATCH("Código",INDIRECT("'"&B13&"'!A"&H13&":A"&H13+20),0)+H13-1 -> 132 | J13: =MATCH("Código",INDIRECT("'"&B13&"'!A"&I13+1&":A"&H13+20),0)+I13 -> 141 | K13: =COUNT(INDIRECT("'"&B13&"'!A"&I13&":A"&J13)) -> 6 | L13: =COUNTIF($F$1:F13,F13) -> 5 | M13: {=IF(Tabela2[[#This Row],[TIPO]]<>"BASE - POSTO FLU",_xlfn.XLOOKUP(Tabela2[[#This Row],[SUBBACIA]],INDIRECT("'"&Tabela2[[#This Row],[MODELO]]&"'!B1:B5000"),INDIRECT("'"&Tabela2[[#This Row],[MODELO]]&"'!A1:A5000")),"")} -> 11 | N13: {=IF(Tabela2[[#This Row],[TIPO]]="BASE - POSTO FLU",OFFSET(INDIRECT("'"&Tabela2[[#This Row],[MODELO]]&"'!A1"),MATCH("Sub-bacia modelada: "&Tabela2[[#This Row],[SUBBACIA]],INDIRECT("'"&Tabela2[[#This Row],[MODELO]]&"'!A1:A5000"),0)+8,0),"")} | O13: {=IF(Tabela2[[#This Row],[TIPO]]="NÃO BASE","",INDEX(INDIRECT("'"&Tabela2[[#This Row],[MODELO]]&"'!$A$1:$A$5000"),MATCH("Precipitação verificada:",OFFSET(INDIRECT("'"&Tabela2[[#This Row],[MODELO]]&"'!$A$1"),MATCH("Sub-bacia modelada: "&Tabela2[[#This Row],[SUBBACIA MODELADA]],INDIRECT("'"&Tabela2[[#This Row],[MODELO]]&"'!$A$1:$A$5000"),0),0,25,1),0)+MATCH("Sub-bacia modelada: "&Tabela2[[#This Row],[SUBBACIA MODELADA]],INDIRECT("'"&Tabela2[[#This Row],[MODELO]]&"'!$A$1:$A$5000"),0)+3))}
A14: =IF(AND(K13>1,L13<>K13),A13,A13+1) -> 7 | B14: SMAP GRANDE E PARANAIBA | C14: SMP_GRPRNB | D14: Grande | E14: {=IF(K14=0,F14,TRIM(OFFSET(INDIRECT("'"&B14&"'!A1"),I14+L14,1)))} -> Porto Colômbia | F14: {=TRIM(SUBSTITUTE(INDEX(INDIRECT("'"&B14&"'!A1:A1000"),H14),"Sub-bacia modelada:",""))} -> Porto Colômbia | G14: =IF(K14=0,"BASE - POSTO FLU",IF(OR(E14=F14,K14=1),"BASE - RESERVATÓRIO","NÃO BASE")) -> BASE - RESERVATÓRIO | H14: {=SMALL(ROW(INDIRECT("'"&B14&"'!A1:A1000"))*IF(ISNUMBER(FIND("Sub-bacia modelada:",INDIRECT("'"&B14&"'!A1:A1000"))),1,9999),RESUMO!A14)} -> 129 | I14: =MATCH("Código",INDIRECT("'"&B14&"'!A"&H14&":A"&H14+20),0)+H14-1 -> 132 | J14: =MATCH("Código",INDIRECT("'"&B14&"'!A"&I14+1&":A"&H14+20),0)+I14 -> 141 | K14: =COUNT(INDIRECT("'"&B14&"'!A"&I14&":A"&J14)) -> 6 | L14: =COUNTIF($F$1:F14,F14) -> 6 | M14: {=IF(Tabela2[[#This Row],[TIPO]]<>"BASE - POSTO FLU",_xlfn.XLOOKUP(Tabela2[[#This Row],[SUBBACIA]],INDIRECT("'"&Tabela2[[#This Row],[MODELO]]&"'!B1:B5000"),INDIRECT("'"&Tabela2[[#This Row],[MODELO]]&"'!A1:A5000")),"")} -> 12 | N14: {=IF(Tabela2[[#This Row],[TIPO]]="BASE - POSTO FLU",OFFSET(INDIRECT("'"&Tabela2[[#This Row],[MODELO]]&"'!A1"),MATCH("Sub-bacia modelada: "&Tabela2[[#This Row],[SUBBACIA]],INDIRECT("'"&Tabela2[[#This Row],[MODELO]]&"'!A1:A5000"),0)+8,0),"")} | O14: {=IF(Tabela2[[#This Row],[TIPO]]="NÃO BASE","",INDEX(INDIRECT("'"&Tabela2[[#This Row],[MODELO]]&"'!$A$1:$A$5000"),MATCH("Precipitação verificada:",OFFSET(INDIRECT("'"&Tabela2[[#This Row],[MODELO]]&"'!$A$1"),MATCH("Sub-bacia modelada: "&Tabela2[[#This Row],[SUBBACIA MODELADA]],INDIRECT("'"&Tabela2[[#This Row],[MODELO]]&"'!$A$1:$A$5000"),0),0,25,1),0)+MATCH("Sub-bacia modelada: "&Tabela2[[#This Row],[SUBBACIA MODELADA]],INDIRECT("'"&Tabela2[[#This Row],[MODELO]]&"'!$A$1:$A$5000"),0)+3))} -> PSATPTC
... A22: =IF(AND(K21>1,L21<>K21),A21,A21+1) -> 13 | B22: SMAP GRANDE E PARANAIBA | C22: SMP_GRPRNB | D22: Paranaíba | E22: {=IF(K22=0,F22,TRIM(OFFSET(INDIRECT("'"&B22&"'!A1"),I22+L22,1)))} -> Corumbá 3 | F22: {=TRIM(SUBSTITUTE(INDEX(INDIRECT("'"&B22&"'!A1:A1000"),H22),"Sub-bacia modelada:",""))} -> Corumbá I | G22: =IF(K22=0,"BASE - POSTO FLU",IF(OR(E22=F22,K22=1),"BASE - RESERVATÓRIO","NÃO BASE")) -> NÃO BASE | H22: {=SMALL(ROW(INDIRECT("'"&B22&"'!A1:A1000"))*IF(ISNUMBER(FIND("Sub-bacia modelada:",INDIRECT("'"&B22&"'!A1:A1000"))),1,9999),RESUMO!A22)} -> 262 | I22: =MATCH("Código",INDIRECT("'"&B22&"'!A"&H22&":A"&H22+20),0)+H22-1 -> 265 | J22: =MATCH("Código",INDIRECT("'"&B22&"'!A"&I22+1&":A"&H22+20),0)+I22 -> 270 | K22: =COUNT(INDIRECT("'"&B22&"'!A"&I22&":A"&J22)) -> 2 | L22: =COUNTIF($F$1:F22,F22) -> 1 | M22: {=IF(Tabela2[[#This Row],[TIPO]]<>"BASE - POSTO FLU",_xlfn.XLOOKUP(Tabela2[[#This Row],[SUBBACIA]],INDIRECT("'"&Tabela2[[#This Row],[MODELO]]&"'!B1:B5000"),INDIRECT("'"&Tabela2[[#This Row],[MODELO]]&"'!A1:A5000")),"")} -> 23 | N22: {=IF(Tabela2[[#This Row],[TIPO]]="BASE - POSTO FLU",OFFSET(INDIRECT("'"&Tabela2[[#This Row],[MODELO]]&"'!A1"),MATCH("Sub-bacia modelada: "&Tabela2[[#This Row],[SUBBACIA]],INDIRECT("'"&Tabela2[[#This Row],[MODELO]]&"'!A1:A5000"),0)+8,0),"")} | O22: {=IF(Tabela2[[#This Row],[TIPO]]="NÃO BASE","",INDEX(INDIRECT("'"&Tabela2[[#This Row],[MODELO]]&"'!$A$1:$A$5000"),MATCH("Precipitação verificada:",OFFSET(INDIRECT("'"&Tabela2[[#This Row],[MODELO]]&"'!$A$1"),MATCH("Sub-bacia modelada: "&Tabela2[[#This Row],[SUBBACIA MODELADA]],INDIRECT("'"&Tabela2[[#This Row],[MODELO]]&"'!$A$1:$A$5000"),0),0,25,1),0)+MATCH("Sub-bacia modelada: "&Tabela2[[#This Row],[SUBBACIA MODELADA]],INDIRECT("'"&Tabela2[[#This Row],[MODELO]]&"'!$A$1:$A$5000"),0)+3))}
A23: =IF(AND(K22>1,L22<>K22),A22,A22+1) -> 13 | B23: SMAP GRANDE E PARANAIBA | C23: SMP_GRPRNB | D23: Paranaíba | E23: {=IF(K23=0,F23,TRIM(OFFSET(INDIRECT("'"&B23&"'!A1"),I23+L23,1)))} -> Corumbá | F23: {=TRIM(SUBSTITUTE(INDEX(INDIRECT("'"&B23&"'!A1:A1000"),H23),"Sub-bacia modelada:",""))} -> Corumbá I | G23: BASE - RESERVATÓRIO | H23: {=SMALL(ROW(INDIRECT("'"&B23&"'!A1:A1000"))*IF(ISNUMBER(FIND("Sub-bacia modelada:",INDIRECT("'"&B23&"'!A1:A1000"))),1,9999),RESUMO!A23)} -> 262 | I23: =MATCH("Código",INDIRECT("'"&B23&"'!A"&H23&":A"&H23+20),0)+H23-1 -> 265 | J23: =MATCH("Código",INDIRECT("'"&B23&"'!A"&I23+1&":A"&H23+20),0)+I23 -> 270 | K23: =COUNT(INDIRECT("'"&B23&"'!A"&I23&":A"&J23)) -> 2 | L23: =COUNTIF($F$1:F23,F23) -> 2 | M23: {=IF(Tabela2[[#This Row],[TIPO]]<>"BASE - POSTO FLU",_xlfn.XLOOKUP(Tabela2[[#This Row],[SUBBACIA]],INDIRECT("'"&Tabela2[[#This Row],[MODELO]]&"'!B1:B5000"),INDIRECT("'"&Tabela2[[#This Row],[MODELO]]&"'!A1:A5000")),"")} -> 209 | N23: {=IF(Tabela2[[#This Row],[TIPO]]="BASE - POSTO FLU",OFFSET(INDIRECT("'"&Tabela2[[#This Row],[MODELO]]&"'!A1"),MATCH("Sub-bacia modelada: "&Tabela2[[#This Row],[SUBBACIA]],INDIRECT("'"&Tabela2[[#This Row],[MODELO]]&"'!A1:A5000"),0)+8,0),"")} | O23: {=IF(Tabela2[[#This Row],[TIPO]]="NÃO BASE","",INDEX(INDIRECT("'"&Tabela2[[#This Row],[MODELO]]&"'!$A$1:$A$5000"),MATCH("Precipitação verificada:",OFFSET(INDIRECT("'"&Tabela2[[#This Row],[MODELO]]&"'!$A$1"),MATCH("Sub-bacia modelada: "&Tabela2[[#This Row],[SUBBACIA MODELADA]],INDIRECT("'"&Tabela2[[#This Row],[MODELO]]&"'!$A$1:$A$5000"),0),0,25,1),0)+MATCH("Sub-bacia modelada: "&Tabela2[[#This Row],[SUBBACIA MODELADA]],INDIRECT("'"&Tabela2[[#This Row],[MODELO]]&"'!$A$1:$A$5000"),0)+3))} -> PSATCBI
A24: =IF(AND(K23>1,L23<>K23),A23,A23+1) -> 14 | B24: SMAP GRANDE E PARANAIBA | C24: SMP_GRPRNB | D24: Paranaíba | E24: {=IF(K24=0,F24,TRIM(OFFSET(INDIRECT("'"&B24&"'!A1"),I24+L24,1)))} -> Batalha | F24: {=TRIM(SUBSTITUTE(INDEX(INDIRECT("'"&B24&"'!A1:A1000"),H24),"Sub-bacia modelada:",""))} -> Serra do Facão | G24: =IF(K24=0,"BASE - POSTO FLU",IF(OR(E24=F24,K24=1),"BASE - RESERVATÓRIO","NÃO BASE")) -> NÃO BASE | H24: {=SMALL(ROW(INDIRECT("'"&B24&"'!A1:A1000"))*IF(ISNUMBER(FIND("Sub-bacia modelada:",INDIRECT("'"&B24&"'!A1:A1000"))),1,9999),RESUMO!A24)} -> 284 | I24: =MATCH("Código",INDIRECT("'"&B24&"'!A"&H24&":A"&H24+20),0)+H24-1 -> 287 | J24: =MATCH("Código",INDIRECT("'"&B24&"'!A"&I24+1&":A"&H24+20),0)+I24 -> 292 | K24: =COUNT(INDIRECT("'"&B24&"'!A"&I24&":A"&J24)) -> 2 | L24: =COUNTIF($F$1:F24,F24) -> 1 | M24: {=IF(Tabela2[[#This Row],[TIPO]]<>"BASE - POSTO FLU",_xlfn.XLOOKUP(Tabela2[[#This Row],[SUBBACIA]],INDIRECT("'"&Tabela2[[#This Row],[MODELO]]&"'!B1:B5000"),INDIRECT("'"&Tabela2[[#This Row],[MODELO]]&"'!A1:A5000")),"")} -> 22 | N24: {=IF(Tabela2[[#This Row],[TIPO]]="BASE - POSTO FLU",OFFSET(INDIRECT("'"&Tabela2[[#This Row],[MODELO]]&"'!A1"),MATCH("Sub-bacia modelada: "&Tabela2[[#This Row],[SUBBACIA]],INDIRECT("'"&Tabela2[[#This Row],[MODELO]]&"'!A1:A5000"),0)+8,0),"")} | O24: {=IF(Tabela2[[#This Row],[TIPO]]="NÃO BASE","",INDEX(INDIRECT("'"&Tabela2[[#This Row],[MODELO]]&"'!$A$1:$A$5000"),MATCH("Precipitação verificada:",OFFSET(INDIRECT("'"&Tabela2[[#This Row],[MODELO]]&"'!$A$1"),MATCH("Sub-bacia modelada: "&Tabela2[[#This Row],[SUBBACIA MODELADA]],INDIRECT("'"&Tabela2[[#This Row],[MODELO]]&"'!$A$1:$A$5000"),0),0,25,1),0)+MATCH("Sub-bacia modelada: "&Tabela2[[#This Row],[SUBBACIA MODELADA]],INDIRECT("'"&Tabela2[[#This Row],[MODELO]]&"'!$A$1:$A$5000"),0)+3))}
A25: =IF(AND(K24>1,L24<>K24),A24,A24+1) -> 14 | B25: SMAP GRANDE E PARANAIBA | C25: SMP_GRPRNB | D25: Paranaíba | E25: {=IF(K25=0,F25,TRIM(OFFSET(INDIRECT("'"&B25&"'!A1"),I25+L25,1)))} -> Serra do Facão | F25: {=TRIM(SUBSTITUTE(INDEX(INDIRECT("'"&B25&"'!A1:A1000"),H25),"Sub-bacia modelada:",""))} -> Serra do Facão | G25: =IF(K25=0,"BASE - POSTO FLU",IF(OR(E25=F25,K25=1),"BASE - RESERVATÓRIO","NÃO BASE")) -> BASE - RESERVATÓRIO | H25: {=SMALL(ROW(INDIRECT("'"&B25&"'!A1:A1000"))*IF(ISNUMBER(FIND("Sub-bacia modelada:",INDIRECT("'"&B25&"'!A1:A1000"))),1,9999),RESUMO!A25)} -> 284 | I25: =MATCH("Código",INDIRECT("'"&B25&"'!A"&H25&":A"&H25+20),0)+H25-1 -> 287 | J25: =MATCH("Código",INDIRECT("'"&B25&"'!A"&I25+1&":A"&H25+20),0)+I25 -> 292 | K25: =COUNT(INDIRECT("'"&B25&"'!A"&I25&":A"&J25)) -> 2 | L25: =COUNTIF($F$1:F25,F25) -> 2 | M25: {=IF(Tabela2[[#This Row],[TIPO]]<>"BASE - POSTO FLU",_xlfn.XLOOKUP(Tabela2[[#This Row],[SUBBACIA]],INDIRECT("'"&Tabela2[[#This Row],[MODELO]]&"'!B1:B5000"),INDIRECT("'"&Tabela2[[#This Row],[MODELO]]&"'!A1:A5000")),"")} -> 251 | N25: {=IF(Tabela2[[#This Row],[TIPO]]="BASE - POSTO FLU",OFFSET(INDIRECT("'"&Tabela2[[#This Row],[MODELO]]&"'!A1"),MATCH("Sub-bacia modelada: "&Tabela2[[#This Row],[SUBBACIA]],INDIRECT("'"&Tabela2[[#This Row],[MODELO]]&"'!A1:A5000"),0)+8,0),"")} | O25: {=IF(Tabela2[[#This Row],[TIPO]]="NÃO BASE","",INDEX(INDIRECT("'"&Tabela2[[#This Row],[MODELO]]&"'!$A$1:$A$5000"),MATCH("Precipitação verificada:",OFFSET(INDIRECT("'"&Tabela2[[#This Row],[MODELO]]&"'!$A$1"),MATCH("Sub-bacia modelada: "&Tabela2[[#This Row],[SUBBACIA MODELADA]],INDIRECT("'"&Tabela2[[#This Row],[MODELO]]&"'!$A$1:$A$5000"),0),0,25,1),0)+MATCH("Sub-bacia modelada: "&Tabela2[[#This Row],[SUBBACIA MODELADA]],INDIRECT("'"&Tabela2[[#This Row],[MODELO]]&"'!$A$1:$A$5000"),0)+3))} -> PSATSFC
A26: =IF(AND(K25>1,L25<>K25),A25,A25+1) -> 15 | B26: SMAP GRANDE E PARANAIBA | C26: SMP_GRPRNB | D26: Paranaíba | E26: {=IF(K26=0,F26,TRIM(OFFSET(INDIRECT("'"&B26&"'!A1"),I26+L26,1)))} -> Emborcação | F26: {=TRIM(SUBSTITUTE(INDEX(INDIRECT("'"&B26&"'!A1:A1000"),H26),"Sub-bacia modelada:",""))} -> Emborcação | G26: =IF(K26=0,"BASE - POSTO FLU",IF(OR(E26=F26,K26=1),"BASE - RESERVATÓRIO","NÃO BASE")) -> BASE - RESERVATÓRIO | H26: {=SMALL(ROW(INDIRECT("'"&B26&"'!A1:A1000"))*IF(ISNUMBER(FIND("Sub-bacia modelada:",INDIRECT("'"&B26&"'!A1:A1000"))),1,9999),RESUMO!A26)} -> 306 | I26: =MATCH("Código",INDIRECT("'"&B26&"'!A"&H26&":A"&H26+20),0)+H26-1 -> 309 | J26: =MATCH("Código",INDIRECT("'"&B26&"'!A"&I26+1&":A"&H26+20),0)+I26 -> 313 | K26: =COUNT(INDIRECT("'"&B26&"'!A"&I26&":A"&J26)) -> 1 | L26: =COUNTIF($F$1:F26,F26) -> 1 | M26: {=IF(Tabela2[[#This Row],[TIPO]]<>"BASE - POSTO FLU",_xlfn.XLOOKUP(Tabela2[[#This Row],[SUBBACIA]],INDIRECT("'"&Tabela2[[#This Row],[MODELO]]&"'!B1:B5000"),INDIRECT("'"&Tabela2[[#This Row],[MODELO]]&"'!A1:A5000")),"")} -> 24 | N26: {=IF(Tabela2[[#This Row],[TIPO]]="BASE - POSTO FLU",OFFSET(INDIRECT("'"&Tabela2[[#This Row],[MODELO]]&"'!A1"),MATCH("Sub-bacia modelada: "&Tabela2[[#This Row],[SUBBACIA]],INDIRECT("'"&Tabela2[[#This Row],[MODELO]]&"'!A1:A5000"),0)+8,0),"")} | O26: {=IF(Tabela2[[#This Row],[TIPO]]="NÃO BASE","",INDEX(INDIRECT("'"&Tabela2[[#This Row],[MODELO]]&"'!$A$1:$A$5000"),MATCH("Precipitação verificada:",OFFSET(INDIRECT("'"&Tabela2[[#This Row],[MODELO]]&"'!$A$1"),MATCH("Sub-bacia modelada: "&Tabela2[[#This Row],[SUBBACIA MODELADA]],INDIRECT("'"&Tabela2[[#This Row],[MODELO]]&"'!$A$1:$A$5000"),0),0,25,1),0)+MATCH("Sub-bacia modelada: "&Tabela2[[#This Row],[SUBBACIA MODELADA]],INDIRECT("'"&Tabela2[[#This Row],[MODELO]]&"'!$A$1:$A$5000"),0)+3))} -> PSATEMB
A27: =IF(AND(K26>1,L26<>K26),A26,A26+1) -> 16 | B27: SMAP GRANDE E PARANAIBA | C27: SMP_GRPRNB | D27: Paranaíba | E27: {=IF(K27=0,F27,TRIM(OFFSET(INDIRECT("'"&B27&"'!A1"),I27+L27,1)))} -> Nova Ponte | F27: {=TRIM(SUBSTITUTE(INDEX(INDIRECT("'"&B27&"'!A1:A1000"),H27),"Sub-bacia modelada:",""))} -> Nova Ponte | G27: =IF(K27=0,"BASE - POSTO FLU",IF(OR(E27=F27,K27=1),"BASE - RESERVATÓRIO","NÃO BASE")) -> BASE - RESERVATÓRIO | H27: {=SMALL(ROW(INDIRECT("'"&B27&"'!A1:A1000"))*IF(ISNUMBER(FIND("Sub-bacia modelada:",INDIRECT("'"&B27&"'!A1:A1000"))),1,9999),RESUMO!A27)} -> 327 | I27: =MATCH("Código",INDIRECT("'"&B27&"'!A"&H27&":A"&H27+20),0)+H27-1 -> 330 | J27: =MATCH("Código",INDIRECT("'"&B27&"'!A"&I27+1&":A"&H27+20),0)+I27 -> 334 | K27: =COUNT(INDIRECT("'"&B27&"'!A"&I27&":A"&J27)) -> 1 | L27: =COUNTIF($F$1:F27,F27) -> 1 | M27: {=IF(Tabela2[[#This Row],[TIPO]]<>"BASE - POSTO FLU",_xlfn.XLOOKUP(Tabela2[[#This Row],[SUBBACIA]],INDIRECT("'"&Tabela2[[#This Row],[MODELO]]&"'!B1:B5000"),INDIRECT("'"&Tabela2[[#This Row],[MODELO]]&"'!A1:A5000")),"")} -> 25 | N27: {=IF(Tabela2[[#This Row],[TIPO]]="BASE - POSTO FLU",OFFSET(INDIRECT("'"&Tabela2[[#This Row],[MODELO]]&"'!A1"),MATCH("Sub-bacia modelada: "&Tabela2[[#This Row],[SUBBACIA]],INDIRECT("'"&Tabela2[[#This Row],[MODELO]]&"'!A1:A5000"),0)+8,0),"")} | O27: {=IF(Tabela2[[#This Row],[TIPO]]="NÃO BASE","",INDEX(INDIRECT("'"&Tabela2[[#This Row],[MODELO]]&"'!$A$1:$A$5000"),MATCH("Precipitação verificada:",OFFSET(INDIRECT("'"&Tabela2[[#This Row],[MODELO]]&"'!$A$1"),MATCH("Sub-bacia modelada: "&Tabela2[[#This Row],[SUBBACIA MODELADA]],INDIRECT("'"&Tabela2[[#This Row],[MODELO]]&"'!$A$1:$A$5000"),0),0,25,1),0)+MATCH("Sub-bacia modelada: "&Tabela2[[#This Row],[SUBBACIA MODELADA]],INDIRECT("'"&Tabela2[[#This Row],[MODELO]]&"'!$A$1:$A$5000"),0)+3))} -> PSATNPTE
A28: =IF(AND(K27>1,L27<>K27),A27,A27+1) -> 17 | B28: SMAP GRANDE E PARANAIBA | C28: SMP_GRPRNB | D28: Paranaíba | E28: {=IF(K28=0,F28,TRIM(OFFSET(INDIRECT("'"&B28&"'!A1"),I28+L28,1)))} -> Capim Branco 2 | F28: {=TRIM(SUBSTITUTE(INDEX(INDIRECT("'"&B28&"'!A1:A1000"),H28),"Sub-bacia modelada:",""))} -> Itumbiara | G28: =IF(K28=0,"BASE - POSTO FLU",IF(OR(E28=F28,K28=1),"BASE - RESERVATÓRIO","NÃO BASE")) -> NÃO BASE | H28: {=SMALL(ROW(INDIRECT("'"&B28&"'!A1:A1000"))*IF(ISNUMBER(FIND("Sub-bacia modelada:",INDIRECT("'"&B28&"'!A1:A1000"))),1,9999),RESUMO!A28)} -> 348 | I28: =MATCH("Código",INDIRECT("'"&B28&"'!A"&H28&":A"&H28+20),0)+H28-1 -> 351 | J28: =MATCH("Código",INDIRECT("'"&B28&"'!A"&I28+1&":A"&H28+20),0)+I28 -> 358 | K28: =COUNT(INDIRECT("'"&B28&"'!A"&I28&":A"&J28)) -> 4 | L28: =COUNTIF($F$1:F28,F28) -> 1 | M28: {=IF(Tabela2[[#This Row],[TIPO]]<>"BASE - POSTO FLU",_xlfn.XLOOKUP(Tabela2[[#This Row],[SUBBACIA]],INDIRECT("'"&Tabela2[[#This Row],[MODELO]]&"'!B1:B5000"),INDIRECT("'"&Tabela2[[#This Row],[MODELO]]&"'!A1:A5000")),"")} -> 28 | N28: {=IF(Tabela2[[#This Row],[TIPO]]="BASE - POSTO FLU",OFFSET(INDIRECT("'"&Tabela2[[#This Row],[MODELO]]&"'!A1"),MATCH("Sub-bacia modelada: "&Tabela2[[#This Row],[SUBBACIA]],INDIRECT("'"&Tabela2[[#This Row],[MODELO]]&"'!A1:A5000"),0)+8,0),"")} | O28: {=IF(Tabela2[[#This Row],[TIPO]]="NÃO BASE","",INDEX(INDIRECT("'"&Tabela2[[#This Row],[MODELO]]&"'!$A$1:$A$5000"),MATCH("Precipitação verificada:",OFFSET(INDIRECT("'"&Tabela2[[#This Row],[MODELO]]&"'!$A$1"),MATCH("Sub-bacia modelada: "&Tabela2[[#This Row],[SUBBACIA MODELADA]],INDIRECT("'"&Tabela2[[#This Row],[MODELO]]&"'!$A$1:$A$5000"),0),0,25,1),0)+MATCH("Sub-bacia modelada: "&Tabela2[[#This Row],[SUBBACIA MODELADA]],INDIRECT("'"&Tabela2[[#This Row],[MODELO]]&"'!$A$1:$A$5000"),0)+3))}
A29: =IF(AND(K28>1,L28<>K28),A28,A28+1) -> 17 | B29: SMAP GRANDE E PARANAIBA | C29: SMP_GRPRNB | D29: Paranaíba | E29: {=IF(K29=0,F29,TRIM(OFFSET(INDIRECT("'"&B29&"'!A1"),I29+L29,1)))} -> Itumbiara | F29: {=TRIM(SUBSTITUTE(INDEX(INDIRECT("'"&B29&"'!A1:A1000"),H29),"Sub-bacia modelada:",""))} -> Itumbiara | G29: =IF(K29=0,"BASE - POSTO FLU",IF(OR(E29=F29,K29=1),"BASE - RESERVATÓRIO","NÃO BASE")) -> BASE - RESERVATÓRIO | H29: {=SMALL(ROW(INDIRECT("'"&B29&"'!A1:A1000"))*IF(ISNUMBER(FIND("Sub-bacia modelada:",INDIRECT("'"&B29&"'!A1:A1000"))),1,9999),RESUMO!A29)} -> 348 | I29: =MATCH("Código",INDIRECT("'"&B29&"'!A"&H29&":A"&H29+20),0)+H29-1 -> 351 | J29: =MATCH("Código",INDIRECT("'"&B29&"'!A"&I29+1&":A"&H29+20),0)+I29 -> 358 | K29: =COUNT(INDIRECT("'"&B29&"'!A"&I29&":A"&J29)) -> 4 | L29: =COUNTIF($F$1:F29,F29) -> 2 | M29: {=IF(Tabela2[[#This Row],[TIPO]]<>"BASE - POSTO FLU",_xlfn.XLOOKUP(Tabela2[[#This Row],[SUBBACIA]],INDIRECT("'"&Tabela2[[#This Row],[MODELO]]&"'!B1:B5000"),INDIRECT("'"&Tabela2[[#This Row],[MODELO]]&"'!A1:A5000")),"")} -> 31 | N29: {=IF(Tabela2[[#This Row],[TIPO]]="BASE - POSTO FLU",OFFSET(INDIRECT("'"&Tabela2[[#This Row],[MODELO]]&"'!A1"),MATCH("Sub-bacia modelada: "&Tabela2[[#This Row],[SUBBACIA]],INDIRECT("'"&Tabela2[[#This Row],[MODELO]]&"'!A1:A5000"),0)+8,0),"")} | O29: {=IF(Tabela2[[#This Row],[TIPO]]="NÃO BASE","",INDEX(INDIRECT("'"&Tabela2[[#This Row],[MODELO]]&"'!$A$1:$A$5000"),MATCH("Precipitação verificada:",OFFSET(INDIRECT("'"&Tabela2[[#This Row],[MODELO]]&"'!$A$1"),MATCH("Sub-bacia modelada: "&Tabela2[[#This Row],[SUBBACIA MODELADA]],INDIRECT("'"&Tabela2[[#This Row],[MODELO]]&"'!$A$1:$A$5000"),0),0,25,1),0)+MATCH("Sub-bacia modelada: "&Tabela2[[#This Row],[SUBBACIA MODELADA]],INDIRECT("'"&Tabela2[[#This Row],[MODELO]]&"'!$A$1:$A$5000"),0)+3))} -> PSATIMBR
A30: =IF(AND(K29>1,L29<>K29),A29,A29+1) -> 17 | B30: SMAP GRANDE E PARANAIBA | C30: SMP_GRPRNB | D30: Paranaíba | E30: {=IF(K30=0,F30,TRIM(OFFSET(INDIRECT("'"&B30&"'!A1"),I30+L30,1)))} -> Miranda | F30: {=TRIM(SUBSTITUTE(INDEX(INDIRECT("'"&B30&"'!A1:A1000"),H30),"Sub-bacia modelada:",""))} -> Itumbiara | G30: =IF(K30=0,"BASE - POSTO FLU",IF(OR(E30=F30,K30=1),"BASE - RESERVATÓRIO","NÃO BASE")) -> NÃO BASE | H30: {=SMALL(ROW(INDIRECT("'"&B30&"'!A1:A1000"))*IF(ISNUMBER(FIND("Sub-bacia modelada:",INDIRECT("'"&B30&"'!A1:A1000"))),1,9999),RESUMO!A30)} -> 348 | I30: =MATCH("Código",INDIRECT("'"&B30&"'!A"&H30&":A"&H30+20),0)+H30-1 -> 351 | J30: =MATCH("Código",INDIRECT("'"&B30&"'!A"&I30+1&":A"&H30+20),0)+I30 -> 358 | K30: =COUNT(INDIRECT("'"&B30&"'!A"&I30&":A"&J30)) -> 4 | L30: =COUNTIF($F$1:F30,F30) -> 3 | M30: {=IF(Tabela2[[#This Row],[TIPO]]<>"BASE - POSTO FLU",_xlfn.XLOOKUP(Tabela2[[#This Row],[SUBBACIA]],INDIRECT("'"&Tabela2[[#This Row],[MODELO]]&"'!B1:B5000"),INDIRECT("'"&Tabela2[[#This Row],[MODELO]]&"'!A1:A5000")),"")} -> 206 | N30: {=IF(Tabela2[[#This Row],[TIPO]]="BASE - POSTO FLU",OFFSET(INDIRECT("'"&Tabela2[[#This Row],[MODELO]]&"'!A1"),MATCH("Sub-bacia modelada: "&Tabela2[[#This Row],[SUBBACIA]],INDIRECT("'"&Tabela2[[#This Row],[MODELO]]&"'!A1:A5000"),0)+8,0),"")} | O30: {=IF(Tabela2[[#This Row],[TIPO]]="NÃO BASE","",INDEX(INDIRECT("'"&Tabela2[[#This Row],[MODELO]]&"'!$A$1:$A$5000"),MATCH("Precipitação verificada:",OFFSET(INDIRECT("'"&Tabela2[[#This Row],[MODELO]]&"'!$A$1"),MATCH("Sub-bacia modelada: "&Tabela2[[#This Row],[SUBBACIA MODELADA]],INDIRECT("'"&Tabela2[[#This Row],[MODELO]]&"'!$A$1:$A$5000"),0),0,25,1),0)+MATCH("Sub-bacia modelada: "&Tabela2[[#This Row],[SUBBACIA MODELADA]],INDIRECT("'"&Tabela2[[#This Row],[MODELO]]&"'!$A$1:$A$5000"),0)+3))}
A31: =IF(AND(K30>1,L30<>K30),A30,A30+1) -> 17 | B31: SMAP GRANDE E PARANAIBA | C31: SMP_GRPRNB | D31: Paranaíba | E31: {=IF(K31=0,F31,TRIM(OFFSET(INDIRECT("'"&B31&"'!A1"),I31+L31,1)))} -> Capim Branco 1 | F31: {=TRIM(SUBSTITUTE(INDEX(INDIRECT("'"&B31&"'!A1:A1000"),H31),"Sub-bacia modelada:",""))} -> Itumbiara | G31: =IF(K31=0,"BASE - POSTO FLU",IF(OR(E31=F31,K31=1),"BASE - RESERVATÓRIO","NÃO BASE")) -> NÃO BASE | H31: {=SMALL(ROW(INDIRECT("'"&B31&"'!A1:A1000"))*IF(ISNUMBER(FIND("Sub-bacia modelada:",INDIRECT("'"&B31&"'!A1:A1000"))),1,9999),RESUMO!A31)} -> 348 | I31: =MATCH("Código",INDIRECT("'"&B31&"'!A"&H31&":A"&H31+20),0)+H31-1 -> 351 | J31: =MATCH("Código",INDIRECT("'"&B31&"'!A"&I31+1&":A"&H31+20),0)+I31 -> 358 | K31: =COUNT(INDIRECT("'"&B31&"'!A"&I31&":A"&J31)) -> 4 | L31: =COUNTIF($F$1:F31,F31) -> 4 | M31: {=IF(Tabela2[[#This Row],[TIPO]]<>"BASE - POSTO FLU",_xlfn.XLOOKUP(Tabela2[[#This Row],[SUBBACIA]],INDIRECT("'"&Tabela2[[#This Row],[MODELO]]&"'!B1:B5000"),INDIRECT("'"&Tabela2[[#This Row],[MODELO]]&"'!A1:A5000")),"")} -> 207 | N31: {=IF(Tabela2[[#This Row],[TIPO]]="BASE - POSTO FLU",OFFSET(INDIRECT("'"&Tabela2[[#This Row],[MODELO]]&"'!A1"),MATCH("Sub-bacia modelada: "&Tabela2[[#This Row],[SUBBACIA]],INDIRECT("'"&Tabela2[[#This Row],[MODELO]]&"'!A1:A5000"),0)+8,0),"")} | O31: {=IF(Tabela2[[#This Row],[TIPO]]="NÃO BASE","",INDEX(INDIRECT("'"&Tabela2[[#This Row],[MODELO]]&"'!$A$1:$A$5000"),MATCH("Precipitação verificada:",OFFSET(INDIRECT("'"&Tabela2[[#This Row],[MODELO]]&"'!$A$1"),MATCH("Sub-bacia modelada: "&Tabela2[[#This Row],[SUBBACIA MODELADA]],INDIRECT("'"&Tabela2[[#This Row],[MODELO]]&"'!$A$1:$A$5000"),0),0,25,1),0)+MATCH("Sub-bacia modelada: "&Tabela2[[#This Row],[SUBBACIA MODELADA]],INDIRECT("'"&Tabela2[[#This Row],[MODELO]]&"'!$A$1:$A$5000"),0)+3))}
A32: =IF(AND(K31>1,L31<>K31),A31,A31+1) -> 18 | B32: SMAP GRANDE E PARANAIBA | C32: SMP_GRPRNB | D32: Paranaíba | E32: {=IF(K32=0,F32,TRIM(OFFSET(INDIRECT("'"&B32&"'!A1"),I32+L32,1)))} -> Abaixo do Rio Verde | F32: {=TRIM(SUBSTITUTE(INDEX(INDIRECT("'"&B32&"'!A1:A1000"),H32),"Sub-bacia modelada:",""))} -> Abaixo do Rio Verde | G32: =IF(K32=0,"BASE - POSTO FLU",IF(OR(E32=F32,K32=1),"BASE - RESERVATÓRIO","NÃO BASE")) -> BASE - POSTO FLU | H32: {=SMALL(ROW(INDIRECT("'"&B32&"'!A1:A1000"))*IF(ISNUMBER(FIND("Sub-bacia modelada:",INDIRECT("'"&B32&"'!A1:A1000"))),1,9999),RESUMO!A32)} -> 372 | I32: =MATCH("Código",INDIRECT("'"&B32&"'!A"&H32&":A"&H32+20),0)+H32-1 -> 375 | J32: =MATCH("Código",INDIRECT("'"&B32&"'!A"&I32+1&":A"&H32+20),0)+I32 -> 379 | K32: =COUNT(INDIRECT("'"&B32&"'!A"&I32&":A"&J32)) -> 0 | L32: =COUNTIF($F$1:F32,F32) -> 1 | M32: {=IF(Tabela2[[#This Row],[TIPO]]<>"BASE - POSTO FLU",_xlfn.XLOOKUP(Tabela2[[#This Row],[SUBBACIA]],INDIRECT("'"&Tabela2[[#This Row],[MODELO]]&"'!B1:B5000"),INDIRECT("'"&Tabela2[[#This Row],[MODELO]]&"'!A1:A5000")),"")} | N32: {=IF(Tabela2[[#This Row],[TIPO]]="BASE - POSTO FLU",OFFSET(INDIRECT("'"&Tabela2[[#This Row],[MODELO]]&"'!A1"),MATCH("Sub-bacia modelada: "&Tabela2[[#This Row],[SUBBACIA]],INDIRECT("'"&Tabela2[[#This Row],[MODELO]]&"'!A1:A5000"),0)+8,0),"")} -> 60805100 | O32: {=IF(Tabela2[[#This Row],[TIPO]]="NÃO BASE","",INDEX(INDIRECT("'"&Tabela2[[#This Row],[MODELO]]&"'!$A$1:$A$5000"),MATCH("Precipitação verificada:",OFFSET(INDIRECT("'"&Tabela2[[#This Row],[MODELO]]&"'!$A$1"),MATCH("Sub-bacia modelada: "&Tabela2[[#This Row],[SUBBACIA MODELADA]],INDIRECT("'"&Tabela2[[#This Row],[MODELO]]&"'!$A$1:$A$5000"),0),0,25,1),0)+MATCH("Sub-bacia modelada: "&Tabela2[[#This Row],[SUBBACIA MODELADA]],INDIRECT("'"&Tabela2[[#This Row],[MODELO]]&"'!$A$1:$A$5000"),0)+3))} -> PSATARV
A33: =IF(AND(K32>1,L32<>K32),A32,A32+1) -> 19 | B33: SMAP GRANDE E PARANAIBA | C33: SMP_GRPRNB | D33: Paranaíba | E33: {=IF(K33=0,F33,TRIM(OFFSET(INDIRECT("'"&B33&"'!A1"),I33+L33,1)))} -> C. Dourada | F33: {=TRIM(SUBSTITUTE(INDEX(INDIRECT("'"&B33&"'!A1:A1000"),H33),"Sub-bacia modelada:",""))} -> São Simão | G33: =IF(K33=0,"BASE - POSTO FLU",IF(OR(E33=F33,K33=1),"BASE - RESERVATÓRIO","NÃO BASE")) -> NÃO BASE | H33: {=SMALL(ROW(INDIRECT("'"&B33&"'!A1:A1000"))*IF(ISNUMBER(FIND("Sub-bacia modelada:",INDIRECT("'"&B33&"'!A1:A1000"))),1,9999),RESUMO!A33)} -> 393 | I33: =MATCH("Código",INDIRECT("'"&B33&"'!A"&H33&":A"&H33+20),0)+H33-1 -> 396 | J33: =MATCH("Código",INDIRECT("'"&B33&"'!A"&I33+1&":A"&H33+20),0)+I33 -> 401 | K33: =COUNT(INDIRECT("'"&B33&"'!A"&I33&":A"&J33)) -> 2 | L33: =COUNTIF($F$1:F33,F33) -> 1 | M33: {=IF(Tabela2[[#This Row],[TIPO]]<>"BASE - POSTO FLU",_xlfn.XLOOKUP(Tabela2[[#This Row],[SUBBACIA]],INDIRECT("'"&Tabela2[[#This Row],[MODELO]]&"'!B1:B5000"),INDIRECT("'"&Tabela2[[#This Row],[MODELO]]&"'!A1:A5000")),"")} -> 32 | N33: {=IF(Tabela2[[#This Row],[TIPO]]="BASE - POSTO FLU",OFFSET(INDIRECT("'"&Tabela2[[#This Row],[MODELO]]&"'!A1"),MATCH("Sub-bacia modelada: "&Tabela2[[#This Row],[SUBBACIA]],INDIRECT("'"&Tabela2[[#This Row],[MODELO]]&"'!A1:A5000"),0)+8,0),"")} | O33: {=IF(Tabela2[[#This Row],[TIPO]]="NÃO BASE","",INDEX(INDIRECT("'"&Tabela2[[#This Row],[MODELO]]&"'!$A$1:$A$5000"),MATCH("Precipitação verificada:",OFFSET(INDIRECT("'"&Tabela2[[#This Row],[MODELO]]&"'!$A$1"),MATCH("Sub-bacia modelada: "&Tabela2[[#This Row],[SUBBACIA MODELADA]],INDIRECT("'"&Tabela2[[#This Row],[MODELO]]&"'!$A$1:$A$5000"),0),0,25,1),0)+MATCH("Sub-bacia modelada: "&Tabela2[[#This Row],[SUBBACIA MODELADA]],INDIRECT("'"&Tabela2[[#This Row],[MODELO]]&"'!$A$1:$A$5000"),0)+3))}
A34: =IF(AND(K33>1,L33<>K33),A33,A33+1) -> 19 | B34: SMAP GRANDE E PARANAIBA | C34: SMP_GRPRNB | D34: Paranaíba | E34: {=IF(K34=0,F34,TRIM(OFFSET(INDIRECT("'"&B34&"'!A1"),I34+L34,1)))} -> São Simão | F34: {=TRIM(SUBSTITUTE(INDEX(INDIRECT("'"&B34&"'!A1:A1000"),H34),"Sub-bacia modelada:",""))} -> São Simão | G34: =IF(K34=0,"BASE - POSTO FLU",IF(OR(E34=F34,K34=1),"BASE - RESERVATÓRIO","NÃO BASE")) -> BASE - RESERVATÓRIO | H34: {=SMALL(ROW(INDIRECT("'"&B34&"'!A1:A1000"))*IF(ISNUMBER(FIND("Sub-bacia modelada:",INDIRECT("'"&B34&"'!A1:A1000"))),1,9999),RESUMO!A34)} -> 393 | I34: =MATCH("Código",INDIRECT("'"&B34&"'!A"&H34&":A"&H34+20),0)+H34-1 -> 396 | J34: =MATCH("Código",INDIRECT("'"&B34&"'!A"&I34+1&":A"&H34+20),0)+I34 -> 401 | K34: =COUNT(INDIRECT("'"&B34&"'!A"&I34&":A"&J34)) -> 2 | L34: =COUNTIF($F$1:F34,F34) -> 2 | M34: {=IF(Tabela2[[#This Row],[TIPO]]<>"BASE - POSTO FLU",_xlfn.XLOOKUP(Tabela2[[#This Row],[SUBBACIA]],INDIRECT("'"&Tabela2[[#This Row],[MODELO]]&"'!B1:B5000"),INDIRECT("'"&Tabela2[[#This Row],[MODELO]]&"'!A1:A5000")),"")} -> 33 | N34: {=IF(Tabela2[[#This Row],[TIPO]]="BASE - POSTO FLU",OFFSET(INDIRECT("'"&Tabela2[[#This Row],[MODELO]]&"'!A1"),MATCH("Sub-bacia modelada: "&Tabela2[[#This Row],[SUBBACIA]],INDIRECT("'"&Tabela2[[#This Row],[MODELO]]&"'!A1:A5000"),0)+8,0),"")} | O34: {=IF(Tabela2[[#This Row],[TIPO]]="NÃO BASE","",INDEX(INDIRECT("'"&Tabela2[[#This Row],[MODELO]]&"'!$A$1:$A$5000"),MATCH("Precipitação verificada:",OFFSET(INDIRECT("'"&Tabela2[[#This Row],[MODELO]]&"'!$A$1"),MATCH("Sub-bacia modelada: "&Tabela2[[#This Row],[SUBBACIA MODELADA]],INDIRECT("'"&Tabela2[[#This Row],[MODELO]]&"'!$A$1:$A$5000"),0),0,25,1),0)+MATCH("Sub-bacia modelada: "&Tabela2[[#This Row],[SUBBACIA MODELADA]],INDIRECT("'"&Tabela2[[#This Row],[MODELO]]&"'!$A$1:$A$5000"),0)+3))} -> PSATSSM
A35: =IF(AND(K34>1,L34<>K34),A34,A34+1) -> 20 | B35: SMAP GRANDE E PARANAIBA | C35: SMP_GRPRNB | D35: Paranaíba | E35: {=IF(K35=0,F35,TRIM(OFFSET(INDIRECT("'"&B35&"'!A1"),I35+L35,1)))} -> Espora | F35: {=TRIM(SUBSTITUTE(INDEX(INDIRECT("'"&B35&"'!A1:A1000"),H35),"Sub-bacia modelada:",""))} -> Espora | G35: =IF(K35=0,"BASE - POSTO FLU",IF(OR(E35=F35,K35=1),"BASE - RESERVATÓRIO","NÃO BASE")) -> BASE - RESERVATÓRIO | H35: {=SMALL(ROW(INDIRECT("'"&B35&"'!A1:A1000"))*IF(ISNUMBER(FIND("Sub-bacia modelada:",INDIRECT("'"&B35&"'!A1:A1000"))),1,9999),RESUMO!A35)} -> 415 | I35: =MATCH("Código",INDIRECT("'"&B35&"'!A"&H35&":A"&H35+20),0)+H35-1 -> 418 | J35: =MATCH("Código",INDIRECT("'"&B35&"'!A"&I35+1&":A"&H35+20),0)+I35 -> 422 | K35: =COUNT(INDIRECT("'"&B35&"'!A"&I35&":A"&J35)) -> 1 | L35: =COUNTIF($F$1:F35,F35) -> 1 | M35: {=IF(Tabela2[[#This Row],[TIPO]]<>"BASE - POSTO FLU",_xlfn.XLOOKUP(Tabela2[[#This Row],[SUBBACIA]],INDIRECT("'"&Tabela2[[#This Row],[MODELO]]&"'!B1:B5000"),INDIRECT("'"&Tabela2[[#This Row],[MODELO]]&"'!A1:A5000")),"")} -> 99 | N35: {=IF(Tabela2[[#This Row],[TIPO]]="BASE - POSTO FLU",OFFSET(INDIRECT("'"&Tabela2[[#This Row],[MODELO]]&"'!A1"),MATCH("Sub-bacia modelada: "&Tabela2[[#This Row],[SUBBACIA]],INDIRECT("'"&Tabela2[[#This Row],[MODELO]]&"'!A1:A5000"),0)+8,0),"")} | O35: {=IF(Tabela2[[#This Row],[TIPO]]="NÃO BASE","",INDEX(INDIRECT("'"&Tabela2[[#This Row],[MODELO]]&"'!$A$1:$A$5000"),MATCH("Precipitação verificada:",OFFSET(INDIRECT("'"&Tabela2[[#This Row],[MODELO]]&"'!$A$1"),MATCH("Sub-bacia modelada: "&Tabela2[[#This Row],[SUBBACIA MODELADA]],INDIRECT("'"&Tabela2[[#This Row],[MODELO]]&"'!$A$1:$A$5000"),0),0,25,1),0)+MATCH("Sub-bacia modelada: "&Tabela2[[#This Row],[SUBBACIA MODELADA]],INDIRECT("'"&Tabela2[[#This Row],[MODELO]]&"'!$A$1:$A$5000"),0)+3))} -> PSATESP
... A38: =IF(AND(K37>1,L37<>K37),A37,A37+1) -> 21 | B38: SMAP GRANDE E PARANAIBA | C38: SMP_GRPRNB | D38: Paranaíba | E38: {=IF(K38=0,F38,TRIM(OFFSET(INDIRECT("'"&B38&"'!A1"),I38+L38,1)))} -> Foz do Rio Claro | F38: {=TRIM(SUBSTITUTE(INDEX(INDIRECT("'"&B38&"'!A1:A1000"),H38),"Sub-bacia modelada:",""))} -> Foz do Rio Claro | G38: =IF(K38=0,"BASE - POSTO FLU",IF(OR(E38=F38,K38=1),"BASE - RESERVATÓRIO","NÃO BASE")) -> BASE - RESERVATÓRIO | H38: {=SMALL(ROW(INDIRECT("'"&B38&"'!A1:A1000"))*IF(ISNUMBER(FIND("Sub-bacia modelada:",INDIRECT("'"&B38&"'!A1:A1000"))),1,9999),RESUMO!A38)} -> 436 | I38: =MATCH("Código",INDIRECT("'"&B38&"'!A"&H38&":A"&H38+20),0)+H38-1 -> 439 | J38: =MATCH("Código",INDIRECT("'"&B38&"'!A"&I38+1&":A"&H38+20),0)+I38 -> 445 | K38: =COUNT(INDIRECT("'"&B38&"'!A"&I38&":A"&J38)) -> 3 | L38: =COUNTIF($F$1:F38,F38) -> 3 | M38: {=IF(Tabela2[[#This Row],[TIPO]]<>"BASE - POSTO FLU",_xlfn.XLOOKUP(Tabela2[[#This Row],[SUBBACIA]],INDIRECT("'"&Tabela2[[#This Row],[MODELO]]&"'!B1:B5000"),INDIRECT("'"&Tabela2[[#This Row],[MODELO]]&"'!A1:A5000")),"")} -> 261 | N38: {=IF(Tabela2[[#This Row],[TIPO]]="BASE - POSTO FLU",OFFSET(INDIRECT("'"&Tabela2[[#This Row],[MODELO]]&"'!A1"),MATCH("Sub-bacia modelada: "&Tabela2[[#This Row],[SUBBACIA]],INDIRECT("'"&Tabela2[[#This Row],[MODELO]]&"'!A1:A5000"),0)+8,0),"")} | O38: {=IF(Tabela2[[#This Row],[TIPO]]="NÃO BASE","",INDEX(INDIRECT("'"&Tabela2[[#This Row],[MODELO]]&"'!$A$1:$A$5000"),MATCH("Precipitação verificada:",OFFSET(INDIRECT("'"&Tabela2[[#This Row],[MODELO]]&"'!$A$1"),MATCH("Sub-bacia modelada: "&Tabela2[[#This Row],[SUBBACIA MODELADA]],INDIRECT("'"&Tabela2[[#This Row],[MODELO]]&"'!$A$1:$A$5000"),0),0,25,1),0)+MATCH("Sub-bacia modelada: "&Tabela2[[#This Row],[SUBBACIA MODELADA]],INDIRECT("'"&Tabela2[[#This Row],[MODELO]]&"'!$A$1:$A$5000"),0)+3))} -> PSATFRCL
A39: =IF(AND(K38>1,L38<>K38),A38,A38+1) -> 22 | B39: SMAP GRANDE E PARANAIBA | C39: SMP_GRPRNB | D39: Paranaíba | E39: {=IF(K39=0,F39,TRIM(OFFSET(INDIRECT("'"&B39&"'!A1"),I39+L39,1)))} -> S.R. Verdinho | F39: {=TRIM(SUBSTITUTE(INDEX(INDIRECT("'"&B39&"'!A1:A1000"),H39),"Sub-bacia modelada:",""))} -> Salto Rio Verdinho | G39: BASE - RESERVATÓRIO | H39: {=SMALL(ROW(INDIRECT("'"&B39&"'!A1:A1000"))*IF(ISNUMBER(FIND("Sub-bacia modelada:",INDIRECT("'"&B39&"'!A1:A1000"))),1,9999),RESUMO!A39)} -> 459 | I39: =MATCH("Código",INDIRECT("'"&B39&"'!A"&H39&":A"&H39+20),0)+H39-1 -> 462 | J39: =MATCH("Código",INDIRECT("'"&B39&"'!A"&I39+1&":A"&H39+20),0)+I39 -> 467 | K39: =COUNT(INDIRECT("'"&B39&"'!A"&I39&":A"&J39)) -> 2 | L39: =COUNTIF($F$1:F39,F39) -> 1 | M39: {=IF(Tabela2[[#This Row],[TIPO]]<>"BASE - POSTO FLU",_xlfn.XLOOKUP(Tabela2[[#This Row],[SUBBACIA]],INDIRECT("'"&Tabela2[[#This Row],[MODELO]]&"'!B1:B5000"),INDIRECT("'"&Tabela2[[#This Row],[MODELO]]&"'!A1:A5000")),"")} -> 241 | N39: {=IF(Tabela2[[#This Row],[TIPO]]="BASE - POSTO FLU",OFFSET(INDIRECT("'"&Tabela2[[#This Row],[MODELO]]&"'!A1"),MATCH("Sub-bacia modelada: "&Tabela2[[#This Row],[SUBBACIA]],INDIRECT("'"&Tabela2[[#This Row],[MODELO]]&"'!A1:A5000"),0)+8,0),"")} | O39: {=IF(Tabela2[[#This Row],[TIPO]]="NÃO BASE","",INDEX(INDIRECT("'"&Tabela2[[#This Row],[MODELO]]&"'!$A$1:$A$5000"),MATCH("Precipitação verificada:",OFFSET(INDIRECT("'"&Tabela2[[#This Row],[MODELO]]&"'!$A$1"),MATCH("Sub-bacia modelada: "&Tabela2[[#This Row],[SUBBACIA MODELADA]],INDIRECT("'"&Tabela2[[#This Row],[MODELO]]&"'!$A$1:$A$5000"),0),0,25,1),0)+MATCH("Sub-bacia modelada: "&Tabela2[[#This Row],[SUBBACIA MODELADA]],INDIRECT("'"&Tabela2[[#This Row],[MODELO]]&"'!$A$1:$A$5000"),0)+3))} -> PSATSRC
A40: =IF(AND(K39>1,L39<>K39),A39,A39+1) -> 22 | B40: SMAP GRANDE E PARANAIBA | C40: SMP_GRPRNB | D40: Paranaíba | E40: {=IF(K40=0,F40,TRIM(OFFSET(INDIRECT("'"&B40&"'!A1"),I40+L40,1)))} -> Salto | F40: {=TRIM(SUBSTITUTE(INDEX(INDIRECT("'"&B40&"'!A1:A1000"),H40),"Sub-bacia modelada:",""))} -> Salto Rio Verdinho | G40: =IF(K40=0,"BASE - POSTO FLU",IF(OR(E40=F40,K40=1),"BASE - RESERVATÓRIO","NÃO BASE")) -> NÃO BASE | H40: {=SMALL(ROW(INDIRECT("'"&B40&"'!A1:A1000"))*IF(ISNUMBER(FIND("Sub-bacia modelada:",INDIRECT("'"&B40&"'!A1:A1000"))),1,9999),RESUMO!A40)} -> 459 | I40: =MATCH("Código",INDIRECT("'"&B40&"'!A"&H40&":A"&H40+20),0)+H40-1 -> 462 | J40: =MATCH("Código",INDIRECT("'"&B40&"'!A"&I40+1&":A"&H40+20),0)+I40 -> 467 | K40: =COUNT(INDIRECT("'"&B40&"'!A"&I40&":A"&J40)) -> 2 | L40: =COUNTIF($F$1:F40,F40) -> 2 | M40: {=IF(Tabela2[[#This Row],[TIPO]]<>"BASE - POSTO FLU",_xlfn.XLOOKUP(Tabela2[[#This Row],[SUBBACIA]],INDIRECT("'"&Tabela2[[#This Row],[MODELO]]&"'!B1:B5000"),INDIRECT("'"&Tabela2[[#This Row],[MODELO]]&"'!A1:A5000")),"")} -> 294 | N40: {=IF(Tabela2[[#This Row],[TIPO]]="BASE - POSTO FLU",OFFSET(INDIRECT("'"&Tabela2[[#This Row],[MODELO]]&"'!A1"),MATCH("Sub-bacia modelada: "&Tabela2[[#This Row],[SUBBACIA]],INDIRECT("'"&Tabela2[[#This Row],[MODELO]]&"'!A1:A5000"),0)+8,0),"")} | O40: {=IF(Tabela2[[#This Row],[TIPO]]="NÃO BASE","",INDEX(INDIRECT("'"&Tabela2[[#This Row],[MODELO]]&"'!$A$1:$A$5000"),MATCH("Precipitação verificada:",OFFSET(INDIRECT("'"&Tabela2[[#This Row],[MODELO]]&"'!$A$1"),MATCH("Sub-bacia modelada: "&Tabela2[[#This Row],[SUBBACIA MODELADA]],INDIRECT("'"&Tabela2[[#This Row],[MODELO]]&"'!$A$1:$A$5000"),0),0,25,1),0)+MATCH("Sub-bacia modelada: "&Tabela2[[#This Row],[SUBBACIA MODELADA]],INDIRECT("'"&Tabela2[[#This Row],[MODELO]]&"'!$A$1:$A$5000"),0)+3))}
A41: 1 | B41: SMAP PARANAZÃO | C41: SMP_PRNzao | D41: Paranapanema | E41: {=IF(K41=0,F41,TRIM(OFFSET(INDIRECT("'"&B41&"'!A1"),I41+L41,1)))} -> Mauá | F41: {=TRIM(SUBSTITUTE(INDEX(INDIRECT("'"&B41&"'!A1:A1000"),H41),"Sub-bacia modelada:",""))} -> Mauá | G41: =IF(K41=0,"BASE - POSTO FLU",IF(OR(E41=F41,K41=1),"BASE - RESERVATÓRIO","NÃO BASE")) -> BASE - RESERVATÓRIO | H41: {=SMALL(ROW(INDIRECT("'"&B41&"'!A1:A1000"))*IF(ISNUMBER(FIND("Sub-bacia modelada:",INDIRECT("'"&B41&"'!A1:A1000"))),1,9999),RESUMO!A41)} -> 2 | I41: =MATCH("Código",INDIRECT("'"&B41&"'!A"&H41&":A"&H41+20),0)+H41-1 -> 5 | J41: =MATCH("Código",INDIRECT("'"&B41&"'!A"&I41+1&":A"&H41+20),0)+I41 -> 9 | K41: =COUNT(INDIRECT("'"&B41&"'!A"&I41&":A"&J41)) -> 1 | L41: =COUNTIF($F$1:F41,F41) -> 1 | M41: {=IF(Tabela2[[#This Row],[TIPO]]<>"BASE - POSTO FLU",_xlfn.XLOOKUP(Tabela2[[#This Row],[SUBBACIA]],INDIRECT("'"&Tabela2[[#This Row],[MODELO]]&"'!B1:B5000"),INDIRECT("'"&Tabela2[[#This Row],[MODELO]]&"'!A1:A5000")),"")} -> 57 | N41: {=IF(Tabela2[[#This Row],[TIPO]]="BASE - POSTO FLU",OFFSET(INDIRECT("'"&Tabela2[[#This Row],[MODELO]]&"'!A1"),MATCH("Sub-bacia modelada: "&Tabela2[[#This Row],[SUBBACIA]],INDIRECT("'"&Tabela2[[#This Row],[MODELO]]&"'!A1:A5000"),0)+8,0),"")} | O41: {=IF(Tabela2[[#This Row],[TIPO]]="NÃO BASE","",INDEX(INDIRECT("'"&Tabela2[[#This Row],[MODELO]]&"'!$A$1:$A$5000"),MATCH("Precipitação verificada:",OFFSET(INDIRECT("'"&Tabela2[[#This Row],[MODELO]]&"'!$A$1"),MATCH("Sub-bacia modelada: "&Tabela2[[#This Row],[SUBBACIA MODELADA]],INDIRECT("'"&Tabela2[[#This Row],[MODELO]]&"'!$A$1:$A$5000"),0),0,25,1),0)+MATCH("Sub-bacia modelada: "&Tabela2[[#This Row],[SUBBACIA MODELADA]],INDIRECT("'"&Tabela2[[#This Row],[MODELO]]&"'!$A$1:$A$5000"),0)+3))} -> PSATMAU
A42: =IF(AND(K41>1,L41<>K41),A41,A41+1) -> 2 | B42: SMAP PARANAZÃO | C42: SMP_PRNzao | D42: Paranapanema | E42: {=IF(K42=0,F42,TRIM(OFFSET(INDIRECT("'"&B42&"'!A1"),I42+L42,1)))} -> Jurumirim | F42: {=TRIM(SUBSTITUTE(INDEX(INDIRECT("'"&B42&"'!A1:A1000"),H42),"Sub-bacia modelada:",""))} -> Jurumirim | G42: =IF(K42=0,"BASE - POSTO FLU",IF(OR(E42=F42,K42=1),"BASE - RESERVATÓRIO","NÃO BASE")) -> BASE - RESERVATÓRIO | H42: {=SMALL(ROW(INDIRECT("'"&B42&"'!A1:A1000"))*IF(ISNUMBER(FIND("Sub-bacia modelada:",INDIRECT("'"&B42&"'!A1:A1000"))),1,9999),RESUMO!A42)} -> 23 | I42: =MATCH("Código",INDIRECT("'"&B42&"'!A"&H42&":A"&H42+20),0)+H42-1 -> 26 | J42: =MATCH("Código",INDIRECT("'"&B42&"'!A"&I42+1&":A"&H42+20),0)+I42 -> 30 | K42: =COUNT(INDIRECT("'"&B42&"'!A"&I42&":A"&J42)) -> 1 | L42: =COUNTIF($F$1:F42,F42) -> 1 | M42: {=IF(Tabela2[[#This Row],[TIPO]]<>"BASE - POSTO FLU",_xlfn.XLOOKUP(Tabela2[[#This Row],[SUBBACIA]],INDIRECT("'"&Tabela2[[#This Row],[MODELO]]&"'!B1:B5000"),INDIRECT("'"&Tabela2[[#This Row],[MODELO]]&"'!A1:A5000")),"")} -> 47 | N42: {=IF(Tabela2[[#This Row],[TIPO]]="BASE - POSTO FLU",OFFSET(INDIRECT("'"&Tabela2[[#This Row],[MODELO]]&"'!A1"),MATCH("Sub-bacia modelada: "&Tabela2[[#This Row],[SUBBACIA]],INDIRECT("'"&Tabela2[[#This Row],[MODELO]]&"'!A1:A5000"),0)+8,0),"")} | O42: {=IF(Tabela2[[#This Row],[TIPO]]="NÃO BASE","",INDEX(INDIRECT("'"&Tabela2[[#This Row],[MODELO]]&"'!$A$1:$A$5000"),MATCH("Precipitação verificada:",OFFSET(INDIRECT("'"&Tabela2[[#This Row],[MODELO]]&"'!$A$1"),MATCH("Sub-bacia modelada: "&Tabela2[[#This Row],[SUBBACIA MODELADA]],INDIRECT("'"&Tabela2[[#This Row],[MODELO]]&"'!$A$1:$A$5000"),0),0,25,1),0)+MATCH("Sub-bacia modelada: "&Tabela2[[#This Row],[SUBBACIA MODELADA]],INDIRECT("'"&Tabela2[[#This Row],[MODELO]]&"'!$A$1:$A$5000"),0)+3))} -> PSATJUR
A43: =IF(AND(K42>1,L42<>K42),A42,A42+1) -> 3 | B43: SMAP PARANAZÃO | C43: SMP_PRNzao | D43: Paranapanema | E43: {=IF(K43=0,F43,TRIM(OFFSET(INDIRECT("'"&B43&"'!A1"),I43+L43,1)))} -> Piraju | F43: {=TRIM(SUBSTITUTE(INDEX(INDIRECT("'"&B43&"'!A1:A1000"),H43),"Sub-bacia modelada:",""))} -> Chavantes | G43: =IF(K43=0,"BASE - POSTO FLU",IF(OR(E43=F43,K43=1),"BASE - RESERVATÓRIO","NÃO BASE")) -> NÃO BASE | H43: {=SMALL(ROW(INDIRECT("'"&B43&"'!A1:A1000"))*IF(ISNUMBER(FIND("Sub-bacia modelada:",INDIRECT("'"&B43&"'!A1:A1000"))),1,9999),RESUMO!A43)} -> 44 | I43: =MATCH("Código",INDIRECT("'"&B43&"'!A"&H43&":A"&H43+20),0)+H43-1 -> 47 | J43: =MATCH("Código",INDIRECT("'"&B43&"'!A"&I43+1&":A"&H43+20),0)+I43 -> 53 | K43: =COUNT(INDIRECT("'"&B43&"'!A"&I43&":A"&J43)) -> 3 | L43: =COUNTIF($F$1:F43,F43) -> 1 | M43: {=IF(Tabela2[[#This Row],[TIPO]]<>"BASE - POSTO FLU",_xlfn.XLOOKUP(Tabela2[[#This Row],[SUBBACIA]],INDIRECT("'"&Tabela2[[#This Row],[MODELO]]&"'!B1:B5000"),INDIRECT("'"&Tabela2[[#This Row],[MODELO]]&"'!A1:A5000")),"")} -> 48 | N43: {=IF(Tabela2[[#This Row],[TIPO]]="BASE - POSTO FLU",OFFSET(INDIRECT("'"&Tabela2[[#This Row],[MODELO]]&"'!A1"),MATCH("Sub-bacia modelada: "&Tabela2[[#This Row],[SUBBACIA]],INDIRECT("'"&Tabela2[[#This Row],[MODELO]]&"'!A1:A5000"),0)+8,0),"")} | O43: {=IF(Tabela2[[#This Row],[TIPO]]="NÃO BASE","",INDEX(INDIRECT("'"&Tabela2[[#This Row],[MODELO]]&"'!$A$1:$A$5000"),MATCH("Precipitação verificada:",OFFSET(INDIRECT("'"&Tabela2[[#This Row],[MODELO]]&"'!$A$1"),MATCH("Sub-bacia modelada: "&Tabela2[[#This Row],[SUBBACIA MODELADA]],INDIRECT("'"&Tabela2[[#This Row],[MODELO]]&"'!$A$1:$A$5000"),0),0,25,1),0)+MATCH("Sub-bacia modelada: "&Tabela2[[#This Row],[SUBBACIA MODELADA]],INDIRECT("'"&Tabela2[[#This Row],[MODELO]]&"'!$A$1:$A$5000"),0)+3))}
